Workbook

Sheet 🏆 Leaderboard
A1: 🏆 Leaderboard
A2: ="👥 "&COUNTA(B4:B100)&" spelare • 🏆 Ledande poäng: "&MAX(D4:D100) -> 👥 14 spelare • 🏆 Ledande poäng: 244
A3: Placering | B3: Namn2 | C3: Namn | D3: Poäng
A4: =IF(D4="","",RANK(D4,$D$4:$D$23,0)) -> 1 | B4: Gina | C4: =IF(A4<=3,CHOOSE(A4,"🏆 ","🥈 ","🥉 ")&B4,B4) -> 🏆 Gina | D4: =Gina!B116 -> 244
A5: =IF(D5="","",RANK(D5,$D$4:$D$23,0)) -> 2 | B5: Erik | C5: =IF(A5<=3,CHOOSE(A5,"🏆 ","🥈 ","🥉 ")&B5,B5) -> 🥈 Erik | D5: =Erik!B116 -> 230
A6: =IF(D6="","",RANK(D6,$D$4:$D$23,0)) -> 3 | B6: Petra | C6: =IF(A6<=3,CHOOSE(A6,"🏆 ","🥈 ","🥉 ")&B6,B6) -> 🥉 Petra | D6: =Petra!B116 -> 226
A7: =IF(D7="","",RANK(D7,$D$4:$D$23,0)) -> 4 | B7: ChatGPT | C7: =IF(A7<=3,CHOOSE(A7,"🏆 ","🥈 ","🥉 ")&B7,B7) -> ChatGPT | D7: =Chatgpt!B116 -> 224
A8: =IF(D8="","",RANK(D8,$D$4:$D$23,0)) -> 5 | B8: Mika | C8: =IF(A8<=3,CHOOSE(A8,"🏆 ","🥈 ","🥉 ")&B8,B8) -> Mika | D8: =Mika!B116 -> 222
A9: =IF(D9="","",RANK(D9,$D$4:$D$23,0)) -> 6 | B9: Kristian | C9: =IF(A9<=3,CHOOSE(A9,"🏆 ","🥈 ","🥉 ")&B9,B9) -> Kristian | D9: =Kristian!B116 -> 220
A10: =IF(D10="","",RANK(D10,$D$4:$D$23,0)) -> 7 | B10: Mli | C10: =IF(A10<=3,CHOOSE(A10,"🏆 ","🥈 ","🥉 ")&B10,B10) -> Mli | D10: =Mli!B116 -> 214
A11: =IF(D11="","",RANK(D11,$D$4:$D$23,0)) -> 8 | B11: Lasse P | C11: =IF(A11<=3,CHOOSE(A11,"🏆 ","🥈 ","🥉 ")&B11,B11) -> Lasse P | D11: =Lasse!B116 -> 210
A12: =IF(D12="","",RANK(D12,$D$4:$D$23,0)) -> 9 | B12: Gordon | C12: =IF(A12<=3,CHOOSE(A12,"🏆 ","🥈 ","🥉 ")&B12,B12) -> Gordon | D12: =Gordon!B116 -> 208
A13: =IF(D13="","",RANK(D13,$D$4:$D$23,0)) -> 10 | B13: Christofer | C13: =IF(A13<=3,CHOOSE(A13,"🏆 ","🥈 ","🥉 ")&B13,B13) -> Christofer | D13: =Christofer!B116 -> 204
A14: =IF(D14="","",RANK(D14,$D$4:$D$23,0)) -> 10 | B14: Yazmine | C14: =IF(A14<=3,CHOOSE(A14,"🏆 ","🥈 ","🥉 ")&B14,B14) -> Yazmine | D14: =yazmine!B116 -> 204
A15: =IF(D15="","",RANK(D15,$D$4:$D$23,0)) -> 12 | B15: Fredde L | C15: =IF(A15<=3,CHOOSE(A15,"🏆 ","🥈 ","🥉 ")&B15,B15) -> Fredde L | D15: =Fredde!B116 -> 180
A16: =IF(D16="","",RANK(D16,$D$4:$D$23,0)) -> 13 | B16: Jeppe | C16: =IF(A16<=3,CHOOSE(A16,"🏆 ","🥈 ","🥉 ")&B16,B16) -> Jeppe | D16: =Jeppe!B116 -> 178
A17: =IF(D17="","",RANK(D17,$D$4:$D$23,0)) -> 14 | B17: Elliott | C17: =IF(A17<=3,CHOOSE(A17,"🏆 ","🥈 ","🥉 ")&B17,B17) -> Elliott | D17: =Elliott!B116 -> 142
A18: =IF(D18="","",RANK(D18,$D$4:$D$23,0))
A19: =IF(D19="","",RANK(D19,$D$4:$D$23,0))
A20: =IF(D20="","",RANK(D20,$D$4:$D$23,0))
A21: =IF(D21="","",RANK(D21,$D$4:$D$23,0))
A22: =IF(D22="","",RANK(D22,$D$4:$D$23,0))
A23: =IF(D23="","",RANK(D23,$D$4:$D$23,0))

Sheet ⚽ Match Center
A1: ⚽ MATCH CENTER | BT1: Matchdatum
BS2: {=_xlfn._xlws.SORT(BT2:BT108)} -> 46184 | BT2: 46184
A3: 📅 Matchdag: | B3: 46198 | BS3: 46185 | BT3: 46185
BS4: 46185 | BT4: 46191
BS5: 46186 | BT5: 46192
BS6: 46186 | BT6: 46198
A7: Match 1 | D7: Match 3 | BS7: 46187 | BT7: 46198
A8: ="⚽ "&INDEX(_xlfn.ANCHORARRAY($AD$9),1) -> ⚽ Tjeckien - Mexico | D8: =IFERROR("⚽ "&INDEX(_xlfn.ANCHORARRAY($AD$9),3),"") -> ⚽ Skottland - Brasilien | AB8: Matchnr | AC8: Tid | AD8: Match | BS8: 46187 | BT8: 46185
A9: ="🕒 "&TEXT(INDEX(_xlfn.ANCHORARRAY($AC$9),1),"tt:mm") -> 🕒 03:00 | D9: =IFERROR("🕒 "&TEXT(INDEX(_xlfn.ANCHORARRAY($AC$9),3),"tt:mm"),"") -> 🕒 00:00 | AB9: {=_xlfn._xlws.FILTER('📊 Resultat & Tabell'!C5:C109,'📊 Resultat & Tabell'!D5:D109=$B$3)} -> 5 | AC9: {=_xlfn._xlws.FILTER('📊 Resultat & Tabell'!E5:E109,'📊 Resultat & Tabell'!D5:D109=$B$3)} -> 0.125 | AD9: {=_xlfn._xlws.FILTER('📊 Resultat & Tabell'!I5:I109&" - "&'📊 Resultat & Tabell'!J5:J109,'📊 Resultat & Tabell'!D5:D109=$B$3)} -> Tjeckien - Mexico | AE9: Gordon | AF9: {=IFERROR(_xlfn.XLOOKUP($AB$9,INDIRECT("'"&AE9&"'!$A$4:$A$107"),INDIRECT("'"&AE9&"'!$F$4:$F$107"))&"-"&_xlfn.XLOOKUP($AB$9,INDIRECT("'"&AE9&"'!$A$4:$A$107"),INDIRECT("'"&AE9&"'!$G$4:$G$107")),"")} -> 1-2 | BS9: 46187 | BT9: 46186
AB10: 6 | AC10: 0.125 | AD10: South Africa - Sydkorea | AE10: Jeppe | AF10: {=IFERROR(_xlfn.XLOOKUP($AB$9,INDIRECT("'"&AE9&"'!$A$4:$A$107"),INDIRECT("'"&AE9&"'!$F$4:$F$107"))&"-"&_xlfn.XLOOKUP($AB$9,INDIRECT("'"&AE9&"'!$A$4:$A$107"),INDIRECT("'"&AE9&"'!$G$4:$G$107")),"")} -> 1-2 | BS10: 46187 | BT10: 46191
A11: Christofer | B11: =_xlfn.XLOOKUP($AB9,Christofer!$A$4:$A$107,Christofer!$F$4:$F$107)&"-"&_xlfn.XLOOKUP($AB9,Christofer!$A$4:$A$107,Christofer!$G$4:$G$107) -> 0-1 | D11: Christofer | E11: =IFERROR(_xlfn.XLOOKUP($AB11,Christofer!$A$4:$A$107,Christofer!$F$4:$F$107)&"-"&_xlfn.XLOOKUP($AB11,Christofer!$A$4:$A$107,Christofer!$G$4:$G$107),"") -> 1-2 | AB11: 17 | AC11: 0 | AD11: Skottland - Brasilien | AE11: Christofer | AF11: {=IFERROR(_xlfn.XLOOKUP($AB$9,INDIRECT("'"&AE9&"'!$A$4:$A$107"),INDIRECT("'"&AE9&"'!$F$4:$F$107"))&"-"&_xlfn.XLOOKUP($AB$9,INDIRECT("'"&AE9&"'!$A$4:$A$107"),INDIRECT("'"&AE9&"'!$G$4:$G$107")),"")} -> 1-2 | BS11: 46187 | BT11: 46192
A12: ChatGPT | B12: =_xlfn.XLOOKUP($AB9,Chatgpt!$A$4:$A$107,Chatgpt!$F$4:$F$107)&"-"&_xlfn.XLOOKUP($AB9,Chatgpt!$A$4:$A$107,Chatgpt!$G$4:$G$107) -> 1-1 | D12: ChatGPT | E12: =IFERROR(_xlfn.XLOOKUP($AB11,Chatgpt!$A$4:$A$107,Chatgpt!$F$4:$F$107)&"-"&_xlfn.XLOOKUP($AB11,Chatgpt!$A$4:$A$107,Chatgpt!$G$4:$G$107),"") -> 1-2 | AB12: 18 | AC12: 0 | AD12: Marocko - Haiti | AE12: Chatgpt | AF12: {=IFERROR(_xlfn.XLOOKUP($AB$9,INDIRECT("'"&AE9&"'!$A$4:$A$107"),INDIRECT("'"&AE9&"'!$F$4:$F$107"))&"-"&_xlfn.XLOOKUP($AB$9,INDIRECT("'"&AE9&"'!$A$4:$A$107"),INDIRECT("'"&AE9&"'!$G$4:$G$107")),"")} -> 1-2 | BS12: 46188 | BT12: 46197
A13: Mika | B13: =_xlfn.XLOOKUP($AB9,Mika!$A$4:$A$107,Mika!$F$4:$F$107)&"-"&_xlfn.XLOOKUP($AB9,Mika!$A$4:$A$107,Mika!$G$4:$G$107) -> 1-1 | D13: Mika | E13: =IFERROR(_xlfn.XLOOKUP($AB11,Mika!$A$4:$A$107,Mika!$F$4:$F$107)&"-"&_xlfn.XLOOKUP($AB11,Mika!$A$4:$A$107,Mika!$G$4:$G$107),"") -> 0-2 | AB13: 29 | AC13: 0.91666667 | AD13: Ecuador - Tyskland | AE13: yazmine | AF13: {=IFERROR(_xlfn.XLOOKUP($AB$9,INDIRECT("'"&AE9&"'!$A$4:$A$107"),INDIRECT("'"&AE9&"'!$F$4:$F$107"))&"-"&_xlfn.XLOOKUP($AB$9,INDIRECT("'"&AE9&"'!$A$4:$A$107"),INDIRECT("'"&AE9&"'!$G$4:$G$107")),"")} -> 1-2 | BS13: 46188 | BT13: 46197
A14: Erik | B14: =_xlfn.XLOOKUP($AB9,Erik!$A$4:$A$107,Erik!$F$4:$F$107)&"-"&_xlfn.XLOOKUP($AB9,Erik!$A$4:$A$107,Erik!$G$4:$G$107) -> 1-1 | D14: Erik | E14: =IFERROR(_xlfn.XLOOKUP($AB11,Erik!$A$4:$A$107,Erik!$F$4:$F$107)&"-"&_xlfn.XLOOKUP($AB9,Erik!$A$4:$A$107,Erik!$G$4:$G$107),"") -> 1-1 | AB14: 30 | AC14: 0.91666667 | AD14: Curaçao - Elfenbenskusten | AE14: Mli | AF14: {=IFERROR(_xlfn.XLOOKUP($AB$9,INDIRECT("'"&AE9&"'!$A$4:$A$107"),INDIRECT("'"&AE9&"'!$F$4:$F$107"))&"-"&_xlfn.XLOOKUP($AB$9,INDIRECT("'"&AE9&"'!$A$4:$A$107"),INDIRECT("'"&AE9&"'!$G$4:$G$107")),"")} -> 1-2 | BS14: 46188 | BT14: 46187
A15: Gina | B15: =_xlfn.XLOOKUP($AB9,Gina!$A$4:$A$107,Gina!$F$4:$F$107)&"-"&_xlfn.XLOOKUP($AB9,Gina!$A$4:$A$107,Gina!$G$4:$G$107) -> 1-2 | D15: Gina | E15: =IFERROR(_xlfn.XLOOKUP($AB11,Gina!$A$4:$A$107,Gina!$F$4:$F$107)&"-"&_xlfn.XLOOKUP($AB11,Gina!$A$4:$A$107,Gina!$G$4:$G$107),"") -> 1-3 | AE15: Mika | AF15: {=IFERROR(_xlfn.XLOOKUP($AB$9,INDIRECT("'"&AE9&"'!$A$4:$A$107"),INDIRECT("'"&AE9&"'!$F$4:$F$107"))&"-"&_xlfn.XLOOKUP($AB$9,INDIRECT("'"&AE9&"'!$A$4:$A$107"),INDIRECT("'"&AE9&"'!$G$4:$G$107")),"")} -> 1-2 | BS15: 46188 | BT15: 46187
A16: Yazmine | B16: =_xlfn.XLOOKUP($AB9,yazmine!$A$4:$A$107,yazmine!$F$4:$F$107)&"-"&_xlfn.XLOOKUP($AB9,yazmine!$A$4:$A$107,yazmine!$G$4:$G$107) -> 2-1 | D16: Yazmine | E16: =IFERROR(_xlfn.XLOOKUP($AB11,yazmine!$A$4:$A$107,yazmine!$F$4:$F$107)&"-"&_xlfn.XLOOKUP($AB9,yazmine!$A$4:$A$107,yazmine!$G$4:$G$107),"") -> 2-1 | AE16: Erik | AF16: {=IFERROR(_xlfn.XLOOKUP($AB$9,INDIRECT("'"&AE9&"'!$A$4:$A$107"),INDIRECT("'"&AE9&"'!$F$4:$F$107"))&"-"&_xlfn.XLOOKUP($AB$9,INDIRECT("'"&AE9&"'!$A$4:$A$107"),INDIRECT("'"&AE9&"'!$G$4:$G$107")),"")} -> 1-2 | BS16: 46189 | BT16: 46193
A17: Lasse P | B17: =_xlfn.XLOOKUP($AB9,Lasse!$A$4:$A$107,Lasse!$F$4:$F$107)&"-"&_xlfn.XLOOKUP($AB9,Lasse!$A$4:$A$107,Lasse!$G$4:$G$107) -> 1-2 | D17: Lasse P | E17: =IFERROR(_xlfn.XLOOKUP($AB11,Lasse!$A$4:$A$107,Lasse!$F$4:$F$107)&"-"&_xlfn.XLOOKUP($AB9,Lasse!$A$4:$A$107,Lasse!$G$4:$G$107),"") -> 1-2 | AE17: Elliott | AF17: {=IFERROR(_xlfn.XLOOKUP($AB$9,INDIRECT("'"&AE9&"'!$A$4:$A$107"),INDIRECT("'"&AE9&"'!$F$4:$F$107"))&"-"&_xlfn.XLOOKUP($AB$9,INDIRECT("'"&AE9&"'!$A$4:$A$107"),INDIRECT("'"&AE9&"'!$G$4:$G$107")),"")} -> 1-2 | BS17: 46189 | BT17: 46193
A18: Mli | B18: =_xlfn.XLOOKUP($AB9,Mli!$A$4:$A$107,Mli!$F$4:$F$107)&"-"&_xlfn.XLOOKUP($AB9,Mli!$A$4:$A$107,Mli!$G$4:$G$107) -> 1-1 | D18: Mli | E18: =IFERROR(_xlfn.XLOOKUP($AB11,Mli!$A$4:$A$107,Mli!$F$4:$F$107)&"-"&_xlfn.XLOOKUP($AB9,Mli!$A$4:$A$107,Mli!$G$4:$G$107),"") -> 1-1 | AE18: Petra | AF18: {=IFERROR(_xlfn.XLOOKUP($AB$9,INDIRECT("'"&AE9&"'!$A$4:$A$107"),INDIRECT("'"&AE9&"'!$F$4:$F$107"))&"-"&_xlfn.XLOOKUP($AB$9,INDIRECT("'"&AE9&"'!$A$4:$A$107"),INDIRECT("'"&AE9&"'!$G$4:$G$107")),"")} -> 1-2 | BS18: 46189 | BT18: 46198
A19: Gordon | B19: =_xlfn.XLOOKUP($AB9,Gordon!$A$4:$A$107,Gordon!$F$4:$F$107)&"-"&_xlfn.XLOOKUP($AB9,Gordon!$A$4:$A$107,Gordon!$G$4:$G$107) -> 1-2 | D19: Gordon | E19: =IFERROR(_xlfn.XLOOKUP($AB11,Gordon!$A$4:$A$107,Gordon!$F$4:$F$107)&"-"&_xlfn.XLOOKUP($AB9,Gordon!$A$4:$A$107,Gordon!$G$4:$G$107),"") -> 1-2 | AE19: Lasse | AF19: {=IFERROR(_xlfn.XLOOKUP($AB$9,INDIRECT("'"&AE9&"'!$A$4:$A$107"),INDIRECT("'"&AE9&"'!$F$4:$F$107"))&"-"&_xlfn.XLOOKUP($AB$9,INDIRECT("'"&AE9&"'!$A$4:$A$107"),INDIRECT("'"&AE9&"'!$G$4:$G$107")),"")} -> 1-2 | BS19: 46190 | BT19: 46198
A20: Jeppe | B20: =_xlfn.XLOOKUP($AB9,Jeppe!$A$4:$A$107,Jeppe!$F$4:$F$107)&"-"&_xlfn.XLOOKUP($AB9,Jeppe!$A$4:$A$107,Jeppe!$G$4:$G$107) -> 2-2 | D20: Jeppe | E20: =IFERROR(_xlfn.XLOOKUP($AB11,Jeppe!$A$4:$A$107,Jeppe!$F$4:$F$107)&"-"&_xlfn.XLOOKUP($AB9,Jeppe!$A$4:$A$107,Jeppe!$G$4:$G$107),"") -> 2-2 | AE20: Gina | AF20: {=IFERROR(_xlfn.XLOOKUP($AB$9,INDIRECT("'"&AE9&"'!$A$4:$A$107"),INDIRECT("'"&AE9&"'!$F$4:$F$107"))&"-"&_xlfn.XLOOKUP($AB$9,INDIRECT("'"&AE9&"'!$A$4:$A$107"),INDIRECT("'"&AE9&"'!$G$4:$G$107")),"")} -> 1-2 | BS20: 46190 | BT20: 46186
A21: Kristian | B21: =_xlfn.XLOOKUP($AB9,Kristian!$A$4:$A$107,Kristian!$F$4:$F$107)&"-"&_xlfn.XLOOKUP($AB9,Kristian!$A$4:$A$107,Kristian!$G$4:$G$107) -> 1-1 | D21: Kristian | E21: =IFERROR(_xlfn.XLOOKUP($AB11,Kristian!$A$4:$A$107,Kristian!$F$4:$F$107)&"-"&_xlfn.XLOOKUP($AB9,Kristian!$A$4:$A$107,Kristian!$G$4:$G$107),"") -> 1-1 | AE21: Fredde | AF21: {=IFERROR(_xlfn.XLOOKUP($AB$9,INDIRECT("'"&AE9&"'!$A$4:$A$107"),INDIRECT("'"&AE9&"'!$F$4:$F$107"))&"-"&_xlfn.XLOOKUP($AB$9,INDIRECT("'"&AE9&"'!$A$4:$A$107"),INDIRECT("'"&AE9&"'!$G$4:$G$107")),"")} -> 1-2 | BS21: 46190 | BT21: 46187
A22: Elliott | B22: =_xlfn.XLOOKUP($AB9,Elliott!$A$4:$A$107,Elliott!$F$4:$F$107)&"-"&_xlfn.XLOOKUP($AB9,Elliott!$A$4:$A$107,Elliott!$G$4:$G$107) -> 1-2 | D22: Elliott | E22: =IFERROR(_xlfn.XLOOKUP($AB11,Elliott!$A$4:$A$107,Elliott!$F$4:$F$107)&"-"&_xlfn.XLOOKUP($AB9,Elliott!$A$4:$A$107,Elliott!$G$4:$G$107),"") -> 2-2 | AE22: Kristian | AF22: {=IFERROR(_xlfn.XLOOKUP($AB$9,INDIRECT("'"&AE9&"'!$A$4:$A$107"),INDIRECT("'"&AE9&"'!$F$4:$F$107"))&"-"&_xlfn.XLOOKUP($AB$9,INDIRECT("'"&AE9&"'!$A$4:$A$107"),INDIRECT("'"&AE9&"'!$G$4:$G$107")),"")} -> 1-2 | BS22: 46190 | BT22: 46193
A23: Fredde L | B23: =_xlfn.XLOOKUP($AB9,Fredde!$A$4:$A$107,Fredde!$F$4:$F$107)&"-"&_xlfn.XLOOKUP($AB9,Fredde!$A$4:$A$107,Fredde!$G$4:$G$107) -> 1-3 | D23: Fredde L | E23: =IFERROR(_xlfn.XLOOKUP($AB11,Fredde!$A$4:$A$107,Fredde!$F$4:$F$107)&"-"&_xlfn.XLOOKUP($AB9,Fredde!$A$4:$A$107,Fredde!$G$4:$G$107),"") -> 2-3 | BS23: 46190 | BT23: 46192
A24: Petra | B24: =_xlfn.XLOOKUP($AB9,Petra!$A$4:$A$107,Petra!$F$4:$F$107)&"-"&_xlfn.XLOOKUP($AB9,Petra!$A$4:$A$107,Petra!$G$4:$G$107) -> 2-3 | D24: Petra | E24: =IFERROR(_xlfn.XLOOKUP($AB11,Petra!$A$4:$A$107,Petra!$F$4:$F$107)&"-"&_xlfn.XLOOKUP($AB9,Petra!$A$4:$A$107,Petra!$G$4:$G$107),"") -> 0-3 | BS24: 46191 | BT24: 46199
BS25: 46191 | BT25: 46199
A26: {=IFERROR("🔥 Folkets tips: "&INDEX(B11:B24,MATCH(MAX(COUNTIF(B11:B24,B11:B24)),COUNTIF(B11:B24,B11:B24),0))&" ("&MAX(COUNTIF(B11:B24,B11:B24))&" personer)","")} -> 🔥 Folkets tips: 1-1 (5 personer) | D26: {=IFERROR("🔥 Folkets tips: "&INDEX(E11:E24,MATCH(MAX(COUNTIF(E11:E24,E11:E24)),COUNTIF(E11:E24,E11:E24),0))&" ("&MAX(COUNTIF(E11:E24,E11:E24))&" personer)","")} -> 🔥 Folkets tips: 1-2 (4 personer) | BS26: 46191 | BT26: 46187
BS27: 46191 | BT27: 46188
BS28: 46192
A29: Match 2 | D29: Match 4 | BS29: 46192 | BT29: 46194
A30: =IFERROR("⚽ "&INDEX(_xlfn.ANCHORARRAY($AD$9),2),"") -> ⚽ South Africa - Sydkorea | D30: =IFERROR("⚽ "&INDEX(_xlfn.ANCHORARRAY($AD$9),4),"") -> ⚽ Marocko - Haiti | BS30: 46192 | BT30: 46193
A31: =IFERROR("🕒 "&TEXT(INDEX(_xlfn.ANCHORARRAY($AC$9),2),"tt:mm"),"") -> 🕒 03:00 | D31: =IFERROR("🕒 "&TEXT(INDEX(_xlfn.ANCHORARRAY($AC$9),4),"tt:mm"),"") -> 🕒 00:00 | BS31: 46193 | BT31: 46198
BS32: 46193 | BT32: 46198
A33: Christofer | B33: =IFERROR(_xlfn.XLOOKUP($AB10,Christofer!$A$4:$A$107,Christofer!$F$4:$F$107)&"-"&_xlfn.XLOOKUP($AB10,Christofer!$A$4:$A$107,Christofer!$G$4:$G$107),"") -> 1-3 | D33: Christofer | E33: =IFERROR(_xlfn.XLOOKUP($AB12,Christofer!$A$4:$A$107,Christofer!$F$4:$F$107)&"-"&_xlfn.XLOOKUP($AB12,Christofer!$A$4:$A$107,Christofer!$G$4:$G$107),"") -> 2-0 | BS33: 46193 | BT33: 46187
A34: ChatGPT | B34: =IFERROR(_xlfn.XLOOKUP($AB10,Chatgpt!$A$4:$A$107,Chatgpt!$F$4:$F$107)&"-"&_xlfn.XLOOKUP($AB10,Chatgpt!$A$4:$A$107,Chatgpt!$G$4:$G$107),"") -> 2-1 | D34: ChatGPT | E34: =IFERROR(_xlfn.XLOOKUP($AB12,Chatgpt!$A$4:$A$107,Chatgpt!$F$4:$F$107)&"-"&_xlfn.XLOOKUP($AB12,Chatgpt!$A$4:$A$107,Chatgpt!$G$4:$G$107),"") -> 2-0 | BS34: 46193 | BT34: 46188
A35: Mika | B35: =IFERROR(_xlfn.XLOOKUP($AB10,Mika!$A$4:$A$107,Mika!$F$4:$F$107)&"-"&_xlfn.XLOOKUP($AB10,Mika!$A$4:$A$107,Mika!$G$4:$G$107),"") -> 0-2 | D35: Mika | E35: =IFERROR(_xlfn.XLOOKUP($AB12,Mika!$A$4:$A$107,Mika!$F$4:$F$107)&"-"&_xlfn.XLOOKUP($AB12,Mika!$A$4:$A$107,Mika!$G$4:$G$107),"") -> 2-0 | BS35: 46193 | BT35: 46194
A36: Erik | B36: =IFERROR(_xlfn.XLOOKUP($AB10,Erik!$A$4:$A$107,Erik!$F$4:$F$107)&"-"&_xlfn.XLOOKUP($AB10,Erik!$A$4:$A$107,Erik!$G$4:$G$107),"") -> 2-1 | D36: Erik | E36: =IFERROR(_xlfn.XLOOKUP($AB12,Erik!$A$4:$A$107,Erik!$F$4:$F$107)&"-"&_xlfn.XLOOKUP($AB12,Erik!$A$4:$A$107,Erik!$G$4:$G$107),"") -> 2-0 | BS36: 46194 | BT36: 46193
A37: Gina | B37: =IFERROR(_xlfn.XLOOKUP($AB10,Gina!$A$4:$A$107,Gina!$F$4:$F$107)&"-"&_xlfn.XLOOKUP($AB10,Gina!$A$4:$A$107,Gina!$G$4:$G$107),"") -> 1-1 | D37: Gina | E37: =IFERROR(_xlfn.XLOOKUP($AB12,Gina!$A$4:$A$107,Gina!$F$4:$F$107)&"-"&_xlfn.XLOOKUP($AB12,Gina!$A$4:$A$107,Gina!$G$4:$G$107),"") -> 3-0 | BS37: 46194 | BT37: 46199
A38: Yazmine | B38: =IFERROR(_xlfn.XLOOKUP($AB10,yazmine!$A$4:$A$107,yazmine!$F$4:$F$107)&"-"&_xlfn.XLOOKUP($AB10,yazmine!$A$4:$A$107,yazmine!$G$4:$G$107),"") -> 1-0 | D38: Yazmine | E38: =IFERROR(_xlfn.XLOOKUP($AB12,yazmine!$A$4:$A$107,yazmine!$F$4:$F$107)&"-"&_xlfn.XLOOKUP($AB12,yazmine!$A$4:$A$107,yazmine!$G$4:$G$107),"") -> 1-1 | BS38: 46194 | BT38: 46199
A39: Lasse P | B39: =IFERROR(_xlfn.XLOOKUP($AB10,Lasse!$A$4:$A$107,Lasse!$F$4:$F$107)&"-"&_xlfn.XLOOKUP($AB10,Lasse!$A$4:$A$107,Lasse!$G$4:$G$107),"") -> 1-2 | D39: Lasse P | E39: =IFERROR(_xlfn.XLOOKUP($AB12,Lasse!$A$4:$A$107,Lasse!$F$4:$F$107)&"-"&_xlfn.XLOOKUP($AB12,Lasse!$A$4:$A$107,Lasse!$G$4:$G$107),"") -> 2-0 | BS39: 46194 | BT39: 46188
A40: Mli | B40: =IFERROR(_xlfn.XLOOKUP($AB10,Mli!$A$4:$A$107,Mli!$F$4:$F$107)&"-"&_xlfn.XLOOKUP($AB10,Mli!$A$4:$A$107,Mli!$G$4:$G$107),"") -> 1-2 | D40: Mli | E40: =IFERROR(_xlfn.XLOOKUP($AB12,Mli!$A$4:$A$107,Mli!$F$4:$F$107)&"-"&_xlfn.XLOOKUP($AB12,Mli!$A$4:$A$107,Mli!$G$4:$G$107),"") -> 2-0 | BS40: 46195 | BT40: 46189
...

Sheet 📊 Resultat & Tabell
A1: 🏆 VM 2026 – Resultat & tabell
A3: Lag per grupp | E3: Matcher/resultat
A4: Grupp A | C4: Matchnr | D4: Matchdatum | E4: Tid | F4: Stad | G4: Fas | H4: Grupp | I4: Hemmalag | J4: Bortalag | K4: Mål H | L4: Mål B | M4: Tecken | N4: Vinnare | P4: Grupp A
A5: A1 | B5: Mexico | C5: 1 | D5: 46184 | E5: 0.875 | F5: Estadio Azteca (Mexico City) | G5: Gruppspel | H5: A | I5: Mexico | J5: South Africa | K5: 2 | L5: 0 | M5: =IF(OR(K5="",L5=""),"",IF(K5>L5,"1",IF(K5<L5,"2","X"))) -> 1 | N5: =IF(M5="","",IF(M5="1",I5,IF(M5="2",J5,"Oavgjort"))) -> Mexico | P5: Lag | Q5: V | R5: O | S5: F | T5: GM | U5: IM | V5: +/- | W5: P
A6: A2 | B6: South Africa | C6: 2 | D6: 46185 | E6: 0.16666667 | F6: Estadio Akron (Guadalajara) | G6: Gruppspel | H6: A | I6: Sydkorea | J6: Tjeckien | K6: 2 | L6: 1 | M6: =IF(OR(K6="",L6=""),"",IF(K6>L6,"1",IF(K6<L6,"2","X"))) -> 1 | N6: =IF(M6="","",IF(M6="1",I6,IF(M6="2",J6,"Oavgjort"))) -> Sydkorea | P6: =B5 -> Mexico | Q6: =SUMPRODUCT(($H$5:$H$76="A")*($I$5:$I$76=P6)*($K$5:$K$76<>"")*($K$5:$K$76>$L$5:$L$76))+SUMPRODUCT(($H$5:$H$76="A")*($J$5:$J$76=P6)*($L$5:$L$76<>"")*($L$5:$L$76>$K$5:$K$76)) -> 3 | R6: =SUMPRODUCT(($H$5:$H$76="A")*(($I$5:$I$76=P6)+($J$5:$J$76=P6))*($K$5:$K$76<>"")*($K$5:$K$76=$L$5:$L$76)) -> 0 | S6: =SUMPRODUCT(($H$5:$H$76="A")*($I$5:$I$76=P6)*($K$5:$K$76<>"")*($K$5:$K$76<$L$5:$L$76))+SUMPRODUCT(($H$5:$H$76="A")*($J$5:$J$76=P6)*($L$5:$L$76<>"")*($L$5:$L$76<$K$5:$K$76)) -> 0 | T6: =SUMIFS($K$5:$K$76,$H$5:$H$76,"A",$I$5:$I$76,P6)+SUMIFS($L$5:$L$76,$H$5:$H$76,"A",$J$5:$J$76,P6) -> 6 | U6: =SUMIFS($L$5:$L$76,$H$5:$H$76,"A",$I$5:$I$76,P6)+SUMIFS($K$5:$K$76,$H$5:$H$76,"A",$J$5:$J$76,P6) -> 0 | V6: =T6-U6 -> 6 | W6: =Q6*3+R6 -> 9
A7: A3 | B7: Sydkorea | C7: 3 | D7: 46191 | E7: 0.75 | F7: Mercedes-Benz Stadium (Atlanta) | G7: Gruppspel | H7: A | I7: Tjeckien | J7: South Africa | K7: 1 | L7: 1 | M7: =IF(OR(K7="",L7=""),"",IF(K7>L7,"1",IF(K7<L7,"2","X"))) -> X | N7: =IF(M7="","",IF(M7="1",I7,IF(M7="2",J7,"Oavgjort"))) -> Oavgjort | P7: =B6 -> South Africa | Q7: =SUMPRODUCT(($H$5:$H$76="A")*($I$5:$I$76=P7)*($K$5:$K$76<>"")*($K$5:$K$76>$L$5:$L$76))+SUMPRODUCT(($H$5:$H$76="A")*($J$5:$J$76=P7)*($L$5:$L$76<>"")*($L$5:$L$76>$K$5:$K$76)) -> 1 | R7: =SUMPRODUCT(($H$5:$H$76="A")*(($I$5:$I$76=P7)+($J$5:$J$76=P7))*($K$5:$K$76<>"")*($K$5:$K$76=$L$5:$L$76)) -> 1 | S7: =SUMPRODUCT(($H$5:$H$76="A")*($I$5:$I$76=P7)*($K$5:$K$76<>"")*($K$5:$K$76<$L$5:$L$76))+SUMPRODUCT(($H$5:$H$76="A")*($J$5:$J$76=P7)*($L$5:$L$76<>"")*($L$5:$L$76<$K$5:$K$76)) -> 1 | T7: =SUMIFS($K$5:$K$76,$H$5:$H$76,"A",$I$5:$I$76,P7)+SUMIFS($L$5:$L$76,$H$5:$H$76,"A",$J$5:$J$76,P7) -> 2 | U7: =SUMIFS($L$5:$L$76,$H$5:$H$76,"A",$I$5:$I$76,P7)+SUMIFS($K$5:$K$76,$H$5:$H$76,"A",$J$5:$J$76,P7) -> 3 | V7: =T7-U7 -> -1 | W7: =Q7*3+R7 -> 4
A8: A4 | B8: Tjeckien | C8: 4 | D8: 46192 | E8: 0.125 | F8: Estadio Akron (Guadalajara) | G8: Gruppspel | H8: A | I8: Mexico | J8: Sydkorea | K8: 1 | L8: 0 | M8: =IF(OR(K8="",L8=""),"",IF(K8>L8,"1",IF(K8<L8,"2","X"))) -> 1 | N8: =IF(M8="","",IF(M8="1",I8,IF(M8="2",J8,"Oavgjort"))) -> Mexico | P8: =B7 -> Sydkorea | Q8: =SUMPRODUCT(($H$5:$H$76="A")*($I$5:$I$76=P8)*($K$5:$K$76<>"")*($K$5:$K$76>$L$5:$L$76))+SUMPRODUCT(($H$5:$H$76="A")*($J$5:$J$76=P8)*($L$5:$L$76<>"")*($L$5:$L$76>$K$5:$K$76)) -> 1 | R8: =SUMPRODUCT(($H$5:$H$76="A")*(($I$5:$I$76=P8)+($J$5:$J$76=P8))*($K$5:$K$76<>"")*($K$5:$K$76=$L$5:$L$76)) -> 0 | S8: =SUMPRODUCT(($H$5:$H$76="A")*($I$5:$I$76=P8)*($K$5:$K$76<>"")*($K$5:$K$76<$L$5:$L$76))+SUMPRODUCT(($H$5:$H$76="A")*($J$5:$J$76=P8)*($L$5:$L$76<>"")*($L$5:$L$76<$K$5:$K$76)) -> 2 | T8: =SUMIFS($K$5:$K$76,$H$5:$H$76,"A",$I$5:$I$76,P8)+SUMIFS($L$5:$L$76,$H$5:$H$76,"A",$J$5:$J$76,P8) -> 2 | U8: =SUMIFS($L$5:$L$76,$H$5:$H$76,"A",$I$5:$I$76,P8)+SUMIFS($K$5:$K$76,$H$5:$H$76,"A",$J$5:$J$76,P8) -> 3 | V8: =T8-U8 -> -1 | W8: =Q8*3+R8 -> 3
A9: Grupp B | C9: 5 | D9: 46198 | E9: 0.125 | F9: Estadio Azteca (Mexico City) | G9: Gruppspel | H9: A | I9: Tjeckien | J9: Mexico | K9: 0 | L9: 3 | M9: =IF(OR(K9="",L9=""),"",IF(K9>L9,"1",IF(K9<L9,"2","X"))) -> 2 | N9: =IF(M9="","",IF(M9="1",I9,IF(M9="2",J9,"Oavgjort"))) -> Mexico | P9: =B8 -> Tjeckien | Q9: =SUMPRODUCT(($H$5:$H$76="A")*($I$5:$I$76=P9)*($K$5:$K$76<>"")*($K$5:$K$76>$L$5:$L$76))+SUMPRODUCT(($H$5:$H$76="A")*($J$5:$J$76=P9)*($L$5:$L$76<>"")*($L$5:$L$76>$K$5:$K$76)) -> 0 | R9: =SUMPRODUCT(($H$5:$H$76="A")*(($I$5:$I$76=P9)+($J$5:$J$76=P9))*($K$5:$K$76<>"")*($K$5:$K$76=$L$5:$L$76)) -> 1 | S9: =SUMPRODUCT(($H$5:$H$76="A")*($I$5:$I$76=P9)*($K$5:$K$76<>"")*($K$5:$K$76<$L$5:$L$76))+SUMPRODUCT(($H$5:$H$76="A")*($J$5:$J$76=P9)*($L$5:$L$76<>"")*($L$5:$L$76<$K$5:$K$76)) -> 2 | T9: =SUMIFS($K$5:$K$76,$H$5:$H$76,"A",$I$5:$I$76,P9)+SUMIFS($L$5:$L$76,$H$5:$H$76,"A",$J$5:$J$76,P9) -> 2 | U9: =SUMIFS($L$5:$L$76,$H$5:$H$76,"A",$I$5:$I$76,P9)+SUMIFS($K$5:$K$76,$H$5:$H$76,"A",$J$5:$J$76,P9) -> 6 | V9: =T9-U9 -> -4 | W9: =Q9*3+R9 -> 1
A10: B1 | B10: Kanada | C10: 6 | D10: 46198 | E10: 0.125 | F10: Estadio BBVA (Monterrey) | G10: Gruppspel | H10: A | I10: South Africa | J10: Sydkorea | K10: 1 | L10: 0 | M10: =IF(OR(K10="",L10=""),"",IF(K10>L10,"1",IF(K10<L10,"2","X"))) -> 1 | N10: =IF(M10="","",IF(M10="1",I10,IF(M10="2",J10,"Oavgjort"))) -> South Africa
A11: B2 | B11: Bosnien och Hercegovina | C11: 7 | D11: 46185 | E11: 0.875 | F11: BMO Field (Toronto) | G11: Gruppspel | H11: B | I11: Kanada | J11: Bosnien och Hercegovina | K11: 1 | L11: 1 | M11: =IF(OR(K11="",L11=""),"",IF(K11>L11,"1",IF(K11<L11,"2","X"))) -> X | N11: =IF(M11="","",IF(M11="1",I11,IF(M11="2",J11,"Oavgjort"))) -> Oavgjort | P11: Grupp B
A12: B3 | B12: Qatar | C12: 8 | D12: 46186 | E12: 0.875 | F12: Levi’s Stadium (San Francisco Bay Area) | G12: Gruppspel | H12: B | I12: Qatar | J12: Schweiz | K12: 1 | L12: 1 | M12: =IF(OR(K12="",L12=""),"",IF(K12>L12,"1",IF(K12<L12,"2","X"))) -> X | N12: =IF(M12="","",IF(M12="1",I12,IF(M12="2",J12,"Oavgjort"))) -> Oavgjort | P12: Lag | Q12: V | R12: O | S12: F | T12: GM | U12: IM | V12: +/- | W12: P
A13: B4 | B13: Schweiz | C13: 9 | D13: 46191 | E13: 0.875 | F13: SoFi Stadium (Los Angeles) | G13: Gruppspel | H13: B | I13: Schweiz | J13: Bosnien och Hercegovina | K13: 4 | L13: 1 | M13: =IF(OR(K13="",L13=""),"",IF(K13>L13,"1",IF(K13<L13,"2","X"))) -> 1 | N13: =IF(M13="","",IF(M13="1",I13,IF(M13="2",J13,"Oavgjort"))) -> Schweiz | P13: =B10 -> Kanada | Q13: =SUMPRODUCT(($H$5:$H$76="B")*($I$5:$I$76=P13)*($K$5:$K$76<>"")*($K$5:$K$76>$L$5:$L$76))+SUMPRODUCT(($H$5:$H$76="B")*($J$5:$J$76=P13)*($L$5:$L$76<>"")*($L$5:$L$76>$K$5:$K$76)) -> 1 | R13: =SUMPRODUCT(($H$5:$H$76="B")*(($I$5:$I$76=P13)+($J$5:$J$76=P13))*($K$5:$K$76<>"")*($K$5:$K$76=$L$5:$L$76)) -> 1 | S13: =SUMPRODUCT(($H$5:$H$76="B")*($I$5:$I$76=P13)*($K$5:$K$76<>"")*($K$5:$K$76<$L$5:$L$76))+SUMPRODUCT(($H$5:$H$76="B")*($J$5:$J$76=P13)*($L$5:$L$76<>"")*($L$5:$L$76<$K$5:$K$76)) -> 1 | T13: =SUMIFS($K$5:$K$76,$H$5:$H$76,"B",$I$5:$I$76,P13)+SUMIFS($L$5:$L$76,$H$5:$H$76,"B",$J$5:$J$76,P13) -> 8 | U13: =SUMIFS($L$5:$L$76,$H$5:$H$76,"B",$I$5:$I$76,P13)+SUMIFS($K$5:$K$76,$H$5:$H$76,"B",$J$5:$J$76,P13) -> 3 | V13: =T13-U13 -> 5 | W13: =Q13*3+R13 -> 4
A14: Grupp C | C14: 10 | D14: 46192 | E14: 0 | F14: BC Place (Vancouver) | G14: Gruppspel | H14: B | I14: Kanada | J14: Qatar | K14: 6 | L14: 0 | M14: =IF(OR(K14="",L14=""),"",IF(K14>L14,"1",IF(K14<L14,"2","X"))) -> 1 | N14: =IF(M14="","",IF(M14="1",I14,IF(M14="2",J14,"Oavgjort"))) -> Kanada | P14: =B11 -> Bosnien och Hercegovina | Q14: =SUMPRODUCT(($H$5:$H$76="B")*($I$5:$I$76=P14)*($K$5:$K$76<>"")*($K$5:$K$76>$L$5:$L$76))+SUMPRODUCT(($H$5:$H$76="B")*($J$5:$J$76=P14)*($L$5:$L$76<>"")*($L$5:$L$76>$K$5:$K$76)) -> 1 | R14: =SUMPRODUCT(($H$5:$H$76="B")*(($I$5:$I$76=P14)+($J$5:$J$76=P14))*($K$5:$K$76<>"")*($K$5:$K$76=$L$5:$L$76)) -> 1 | S14: =SUMPRODUCT(($H$5:$H$76="B")*($I$5:$I$76=P14)*($K$5:$K$76<>"")*($K$5:$K$76<$L$5:$L$76))+SUMPRODUCT(($H$5:$H$76="B")*($J$5:$J$76=P14)*($L$5:$L$76<>"")*($L$5:$L$76<$K$5:$K$76)) -> 1 | T14: =SUMIFS($K$5:$K$76,$H$5:$H$76,"B",$I$5:$I$76,P14)+SUMIFS($L$5:$L$76,$H$5:$H$76,"B",$J$5:$J$76,P14) -> 5 | U14: =SUMIFS($L$5:$L$76,$H$5:$H$76,"B",$I$5:$I$76,P14)+SUMIFS($K$5:$K$76,$H$5:$H$76,"B",$J$5:$J$76,P14) -> 6 | V14: =T14-U14 -> -1 | W14: =Q14*3+R14 -> 4
A15: C1 | B15: Brasilien | C15: 11 | D15: 46197 | E15: 0.875 | F15: BC Place (Vancouver) | G15: Gruppspel | H15: B | I15: Schweiz | J15: Kanada | K15: 2 | L15: 1 | M15: =IF(OR(K15="",L15=""),"",IF(K15>L15,"1",IF(K15<L15,"2","X"))) -> 1 | N15: =IF(M15="","",IF(M15="1",I15,IF(M15="2",J15,"Oavgjort"))) -> Schweiz | P15: =B12 -> Qatar | Q15: =SUMPRODUCT(($H$5:$H$76="B")*($I$5:$I$76=P15)*($K$5:$K$76<>"")*($K$5:$K$76>$L$5:$L$76))+SUMPRODUCT(($H$5:$H$76="B")*($J$5:$J$76=P15)*($L$5:$L$76<>"")*($L$5:$L$76>$K$5:$K$76)) -> 0 | R15: =SUMPRODUCT(($H$5:$H$76="B")*(($I$5:$I$76=P15)+($J$5:$J$76=P15))*($K$5:$K$76<>"")*($K$5:$K$76=$L$5:$L$76)) -> 1 | S15: =SUMPRODUCT(($H$5:$H$76="B")*($I$5:$I$76=P15)*($K$5:$K$76<>"")*($K$5:$K$76<$L$5:$L$76))+SUMPRODUCT(($H$5:$H$76="B")*($J$5:$J$76=P15)*($L$5:$L$76<>"")*($L$5:$L$76<$K$5:$K$76)) -> 2 | T15: =SUMIFS($K$5:$K$76,$H$5:$H$76,"B",$I$5:$I$76,P15)+SUMIFS($L$5:$L$76,$H$5:$H$76,"B",$J$5:$J$76,P15) -> 2 | U15: =SUMIFS($L$5:$L$76,$H$5:$H$76,"B",$I$5:$I$76,P15)+SUMIFS($K$5:$K$76,$H$5:$H$76,"B",$J$5:$J$76,P15) -> 10 | V15: =T15-U15 -> -8 | W15: =Q15*3+R15 -> 1
A16: C2 | B16: Marocko | C16: 12 | D16: 46197 | E16: 0.875 | F16: Lumen Field (Seattle) | G16: Gruppspel | H16: B | I16: Bosnien och Hercegovina | J16: Qatar | K16: 3 | L16: 1 | M16: =IF(OR(K16="",L16=""),"",IF(K16>L16,"1",IF(K16<L16,"2","X"))) -> 1 | N16: =IF(M16="","",IF(M16="1",I16,IF(M16="2",J16,"Oavgjort"))) -> Bosnien och Hercegovina | P16: =B13 -> Schweiz | Q16: =SUMPRODUCT(($H$5:$H$76="B")*($I$5:$I$76=P16)*($K$5:$K$76<>"")*($K$5:$K$76>$L$5:$L$76))+SUMPRODUCT(($H$5:$H$76="B")*($J$5:$J$76=P16)*($L$5:$L$76<>"")*($L$5:$L$76>$K$5:$K$76)) -> 2 | R16: =SUMPRODUCT(($H$5:$H$76="B")*(($I$5:$I$76=P16)+($J$5:$J$76=P16))*($K$5:$K$76<>"")*($K$5:$K$76=$L$5:$L$76)) -> 1 | S16: =SUMPRODUCT(($H$5:$H$76="B")*($I$5:$I$76=P16)*($K$5:$K$76<>"")*($K$5:$K$76<$L$5:$L$76))+SUMPRODUCT(($H$5:$H$76="B")*($J$5:$J$76=P16)*($L$5:$L$76<>"")*($L$5:$L$76<$K$5:$K$76)) -> 0 | T16: =SUMIFS($K$5:$K$76,$H$5:$H$76,"B",$I$5:$I$76,P16)+SUMIFS($L$5:$L$76,$H$5:$H$76,"B",$J$5:$J$76,P16) -> 7 | U16: =SUMIFS($L$5:$L$76,$H$5:$H$76,"B",$I$5:$I$76,P16)+SUMIFS($K$5:$K$76,$H$5:$H$76,"B",$J$5:$J$76,P16) -> 3 | V16: =T16-U16 -> 4 | W16: =Q16*3+R16 -> 7
A17: C3 | B17: Haiti | C17: 13 | D17: 46187 | E17: 0 | F17: MetLife Stadium (New York/New Jersey) | G17: Gruppspel | H17: C | I17: Brasilien | J17: Marocko | K17: 1 | L17: 1 | M17: =IF(OR(K17="",L17=""),"",IF(K17>L17,"1",IF(K17<L17,"2","X"))) -> X | N17: =IF(M17="","",IF(M17="1",I17,IF(M17="2",J17,"Oavgjort"))) -> Oavgjort
A18: C4 | B18: Skottland | C18: 14 | D18: 46187 | E18: 0.125 | F18: Gillette Stadium (Boston) | G18: Gruppspel | H18: C | I18: Haiti | J18: Skottland | K18: 0 | L18: 1 | M18: =IF(OR(K18="",L18=""),"",IF(K18>L18,"1",IF(K18<L18,"2","X"))) -> 2 | N18: =IF(M18="","",IF(M18="1",I18,IF(M18="2",J18,"Oavgjort"))) -> Skottland | P18: Grupp C
A19: Grupp D | C19: 15 | D19: 46193 | E19: 0 | F19: Gillette Stadium (Boston) | G19: Gruppspel | H19: C | I19: Skottland | J19: Marocko | K19: 0 | L19: 1 | M19: =IF(OR(K19="",L19=""),"",IF(K19>L19,"1",IF(K19<L19,"2","X"))) -> 2 | N19: =IF(M19="","",IF(M19="1",I19,IF(M19="2",J19,"Oavgjort"))) -> Marocko | P19: Lag | Q19: V | R19: O | S19: F | T19: GM | U19: IM | V19: +/- | W19: P
A20: D1 | B20: USA | C20: 16 | D20: 46193 | E20: 0.97916667 | F20: Lincoln Financial Field (Philadelphia) | G20: Gruppspel | H20: C | I20: Brasilien | J20: Haiti | K20: 3 | L20: 0 | M20: =IF(OR(K20="",L20=""),"",IF(K20>L20,"1",IF(K20<L20,"2","X"))) -> 1 | N20: =IF(M20="","",IF(M20="1",I20,IF(M20="2",J20,"Oavgjort"))) -> Brasilien | P20: =B15 -> Brasilien | Q20: =SUMPRODUCT(($H$5:$H$76="C")*($I$5:$I$76=P20)*($K$5:$K$76<>"")*($K$5:$K$76>$L$5:$L$76))+SUMPRODUCT(($H$5:$H$76="C")*($J$5:$J$76=P20)*($L$5:$L$76<>"")*($L$5:$L$76>$K$5:$K$76)) -> 2 | R20: =SUMPRODUCT(($H$5:$H$76="C")*(($I$5:$I$76=P20)+($J$5:$J$76=P20))*($K$5:$K$76<>"")*($K$5:$K$76=$L$5:$L$76)) -> 1 | S20: =SUMPRODUCT(($H$5:$H$76="C")*($I$5:$I$76=P20)*($K$5:$K$76<>"")*($K$5:$K$76<$L$5:$L$76))+SUMPRODUCT(($H$5:$H$76="C")*($J$5:$J$76=P20)*($L$5:$L$76<>"")*($L$5:$L$76<$K$5:$K$76)) -> 0 | T20: =SUMIFS($K$5:$K$76,$H$5:$H$76,"C",$I$5:$I$76,P20)+SUMIFS($L$5:$L$76,$H$5:$H$76,"C",$J$5:$J$76,P20) -> 7 | U20: =SUMIFS($L$5:$L$76,$H$5:$H$76,"C",$I$5:$I$76,P20)+SUMIFS($K$5:$K$76,$H$5:$H$76,"C",$J$5:$J$76,P20) -> 1 | V20: =T20-U20 -> 6 | W20: =Q20*3+R20 -> 7
A21: D2 | B21: Paraguay | C21: 17 | D21: 46198 | E21: 0 | F21: Hard Rock Stadium (Miami) | G21: Gruppspel | H21: C | I21: Skottland | J21: Brasilien | K21: 0 | L21: 3 | M21: =IF(OR(K21="",L21=""),"",IF(K21>L21,"1",IF(K21<L21,"2","X"))) -> 2 | N21: =IF(M21="","",IF(M21="1",I21,IF(M21="2",J21,"Oavgjort"))) -> Brasilien | P21: =B16 -> Marocko | Q21: =SUMPRODUCT(($H$5:$H$76="C")*($I$5:$I$76=P21)*($K$5:$K$76<>"")*($K$5:$K$76>$L$5:$L$76))+SUMPRODUCT(($H$5:$H$76="C")*($J$5:$J$76=P21)*($L$5:$L$76<>"")*($L$5:$L$76>$K$5:$K$76)) -> 2 | R21: =SUMPRODUCT(($H$5:$H$76="C")*(($I$5:$I$76=P21)+($J$5:$J$76=P21))*($K$5:$K$76<>"")*($K$5:$K$76=$L$5:$L$76)) -> 1 | S21: =SUMPRODUCT(($H$5:$H$76="C")*($I$5:$I$76=P21)*($K$5:$K$76<>"")*($K$5:$K$76<$L$5:$L$76))+SUMPRODUCT(($H$5:$H$76="C")*($J$5:$J$76=P21)*($L$5:$L$76<>"")*($L$5:$L$76<$K$5:$K$76)) -> 0 | T21: =SUMIFS($K$5:$K$76,$H$5:$H$76,"C",$I$5:$I$76,P21)+SUMIFS($L$5:$L$76,$H$5:$H$76,"C",$J$5:$J$76,P21) -> 6 | U21: =SUMIFS($L$5:$L$76,$H$5:$H$76,"C",$I$5:$I$76,P21)+SUMIFS($K$5:$K$76,$H$5:$H$76,"C",$J$5:$J$76,P21) -> 3 | V21: =T21-U21 -> 3 | W21: =Q21*3+R21 -> 7
A22: D3 | B22: Australien | C22: 18 | D22: 46198 | E22: 0 | F22: Mercedes-Benz Stadium (Atlanta) | G22: Gruppspel | H22: C | I22: Marocko | J22: Haiti | K22: 4 | L22: 2 | M22: =IF(OR(K22="",L22=""),"",IF(K22>L22,"1",IF(K22<L22,"2","X"))) -> 1 | N22: =IF(M22="","",IF(M22="1",I22,IF(M22="2",J22,"Oavgjort"))) -> Marocko | P22: =B17 -> Haiti | Q22: =SUMPRODUCT(($H$5:$H$76="C")*($I$5:$I$76=P22)*($K$5:$K$76<>"")*($K$5:$K$76>$L$5:$L$76))+SUMPRODUCT(($H$5:$H$76="C")*($J$5:$J$76=P22)*($L$5:$L$76<>"")*($L$5:$L$76>$K$5:$K$76)) -> 0 | R22: =SUMPRODUCT(($H$5:$H$76="C")*(($I$5:$I$76=P22)+($J$5:$J$76=P22))*($K$5:$K$76<>"")*($K$5:$K$76=$L$5:$L$76)) -> 0 | S22: =SUMPRODUCT(($H$5:$H$76="C")*($I$5:$I$76=P22)*($K$5:$K$76<>"")*($K$5:$K$76<$L$5:$L$76))+SUMPRODUCT(($H$5:$H$76="C")*($J$5:$J$76=P22)*($L$5:$L$76<>"")*($L$5:$L$76<$K$5:$K$76)) -> 3 | T22: =SUMIFS($K$5:$K$76,$H$5:$H$76,"C",$I$5:$I$76,P22)+SUMIFS($L$5:$L$76,$H$5:$H$76,"C",$J$5:$J$76,P22) -> 2 | U22: =SUMIFS($L$5:$L$76,$H$5:$H$76,"C",$I$5:$I$76,P22)+SUMIFS($K$5:$K$76,$H$5:$H$76,"C",$J$5:$J$76,P22) -> 8 | V22: =T22-U22 -> -6 | W22: =Q22*3+R22 -> 0
A23: D4 | B23: Turkiet | C23: 19 | D23: 46186 | E23: 0.125 | F23: SoFi Stadium (Los Angeles) | G23: Gruppspel | H23: D | I23: USA | J23: Paraguay | K23: 4 | L23: 1 | M23: =IF(OR(K23="",L23=""),"",IF(K23>L23,"1",IF(K23<L23,"2","X"))) -> 1 | N23: =IF(M23="","",IF(M23="1",I23,IF(M23="2",J23,"Oavgjort"))) -> USA | P23: =B18 -> Skottland | Q23: =SUMPRODUCT(($H$5:$H$76="C")*($I$5:$I$76=P23)*($K$5:$K$76<>"")*($K$5:$K$76>$L$5:$L$76))+SUMPRODUCT(($H$5:$H$76="C")*($J$5:$J$76=P23)*($L$5:$L$76<>"")*($L$5:$L$76>$K$5:$K$76)) -> 1 | R23: =SUMPRODUCT(($H$5:$H$76="C")*(($I$5:$I$76=P23)+($J$5:$J$76=P23))*($K$5:$K$76<>"")*($K$5:$K$76=$L$5:$L$76)) -> 0 | S23: =SUMPRODUCT(($H$5:$H$76="C")*($I$5:$I$76=P23)*($K$5:$K$76<>"")*($K$5:$K$76<$L$5:$L$76))+SUMPRODUCT(($H$5:$H$76="C")*($J$5:$J$76=P23)*($L$5:$L$76<>"")*($L$5:$L$76<$K$5:$K$76)) -> 2 | T23: =SUMIFS($K$5:$K$76,$H$5:$H$76,"C",$I$5:$I$76,P23)+SUMIFS($L$5:$L$76,$H$5:$H$76,"C",$J$5:$J$76,P23) -> 1 | U23: =SUMIFS($L$5:$L$76,$H$5:$H$76,"C",$I$5:$I$76,P23)+SUMIFS($K$5:$K$76,$H$5:$H$76,"C",$J$5:$J$76,P23) -> 4 | V23: =T23-U23 -> -3 | W23: =Q23*3+R23 -> 3
A24: Grupp E | C24: 20 | D24: 46187 | E24: 0.25 | F24: BC Place (Vancouver) | G24: Gruppspel | H24: D | I24: Australien | J24: Turkiet | K24: 2 | L24: 0 | M24: =IF(OR(K24="",L24=""),"",IF(K24>L24,"1",IF(K24<L24,"2","X"))) -> 1 | N24: =IF(M24="","",IF(M24="1",I24,IF(M24="2",J24,"Oavgjort"))) -> Australien
A25: E1 | B25: Tyskland | C25: 21 | D25: 46193 | E25: 0.875 | F25: Levi’s Stadium (San Francisco Bay Area) | G25: Gruppspel | H25: D | I25: Turkiet | J25: Paraguay | K25: 0 | L25: 1 | M25: =IF(OR(K25="",L25=""),"",IF(K25>L25,"1",IF(K25<L25,"2","X"))) -> 2 | N25: =IF(M25="","",IF(M25="1",I25,IF(M25="2",J25,"Oavgjort"))) -> Paraguay | P25: Grupp D
A26: E2 | B26: Curaçao | C26: 22 | D26: 46192 | E26: 0.20833333 | F26: Lumen Field (Seattle) | G26: Gruppspel | H26: D | I26: USA | J26: Australien | K26: 2 | L26: 0 | M26: =IF(OR(K26="",L26=""),"",IF(K26>L26,"1",IF(K26<L26,"2","X"))) -> 1 | N26: =IF(M26="","",IF(M26="1",I26,IF(M26="2",J26,"Oavgjort"))) -> USA | P26: Lag | Q26: V | R26: O | S26: F | T26: GM | U26: IM | V26: +/- | W26: P
A27: E3 | B27: Elfenbenskusten | C27: 23 | D27: 46199 | E27: 0.16666667 | F27: SoFi Stadium (Los Angeles) | G27: Gruppspel | H27: D | I27: Turkiet | J27: USA | K27: 3 | L27: 2 | M27: =IF(OR(K27="",L27=""),"",IF(K27>L27,"1",IF(K27<L27,"2","X"))) -> 1 | N27: =IF(M27="","",IF(M27="1",I27,IF(M27="2",J27,"Oavgjort"))) -> Turkiet | P27: =B20 -> USA | Q27: =SUMPRODUCT(($H$5:$H$76="D")*($I$5:$I$76=P27)*($K$5:$K$76<>"")*($K$5:$K$76>$L$5:$L$76))+SUMPRODUCT(($H$5:$H$76="D")*($J$5:$J$76=P27)*($L$5:$L$76<>"")*($L$5:$L$76>$K$5:$K$76)) -> 2 | R27: =SUMPRODUCT(($H$5:$H$76="D")*(($I$5:$I$76=P27)+($J$5:$J$76=P27))*($K$5:$K$76<>"")*($K$5:$K$76=$L$5:$L$76)) -> 0 | S27: =SUMPRODUCT(($H$5:$H$76="D")*($I$5:$I$76=P27)*($K$5:$K$76<>"")*($K$5:$K$76<$L$5:$L$76))+SUMPRODUCT(($H$5:$H$76="D")*($J$5:$J$76=P27)*($L$5:$L$76<>"")*($L$5:$L$76<$K$5:$K$76)) -> 1 | T27: =SUMIFS($K$5:$K$76,$H$5:$H$76,"D",$I$5:$I$76,P27)+SUMIFS($L$5:$L$76,$H$5:$H$76,"D",$J$5:$J$76,P27) -> 8 | U27: =SUMIFS($L$5:$L$76,$H$5:$H$76,"D",$I$5:$I$76,P27)+SUMIFS($K$5:$K$76,$H$5:$H$76,"D",$J$5:$J$76,P27) -> 4 | V27: =T27-U27 -> 4 | W27: =Q27*3+R27 -> 6
A28: E4 | B28: Ecuador | C28: 24 | D28: 46199 | E28: 0.16666667 | F28: Levi’s Stadium (San Francisco Bay Area) | G28: Gruppspel | H28: D | I28: Paraguay | J28: Australien | K28: 0 | L28: 0 | M28: =IF(OR(K28="",L28=""),"",IF(K28>L28,"1",IF(K28<L28,"2","X"))) -> X | N28: =IF(M28="","",IF(M28="1",I28,IF(M28="2",J28,"Oavgjort"))) -> Oavgjort | P28: =B21 -> Paraguay | Q28: =SUMPRODUCT(($H$5:$H$76="D")*($I$5:$I$76=P28)*($K$5:$K$76<>"")*($K$5:$K$76>$L$5:$L$76))+SUMPRODUCT(($H$5:$H$76="D")*($J$5:$J$76=P28)*($L$5:$L$76<>"")*($L$5:$L$76>$K$5:$K$76)) -> 1 | R28: =SUMPRODUCT(($H$5:$H$76="D")*(($I$5:$I$76=P28)+($J$5:$J$76=P28))*($K$5:$K$76<>"")*($K$5:$K$76=$L$5:$L$76)) -> 1 | S28: =SUMPRODUCT(($H$5:$H$76="D")*($I$5:$I$76=P28)*($K$5:$K$76<>"")*($K$5:$K$76<$L$5:$L$76))+SUMPRODUCT(($H$5:$H$76="D")*($J$5:$J$76=P28)*($L$5:$L$76<>"")*($L$5:$L$76<$K$5:$K$76)) -> 1 | T28: =SUMIFS($K$5:$K$76,$H$5:$H$76,"D",$I$5:$I$76,P28)+SUMIFS($L$5:$L$76,$H$5:$H$76,"D",$J$5:$J$76,P28) -> 2 | U28: =SUMIFS($L$5:$L$76,$H$5:$H$76,"D",$I$5:$I$76,P28)+SUMIFS($K$5:$K$76,$H$5:$H$76,"D",$J$5:$J$76,P28) -> 4 | V28: =T28-U28 -> -2 | W28: =Q28*3+R28 -> 4
A29: Grupp F | C29: 25 | D29: 46187 | E29: 0.79166667 | F29: NRG Stadium (Houston) | G29: Gruppspel | H29: E | I29: Tyskland | J29: Curaçao | K29: 7 | L29: 1 | M29: =IF(OR(K29="",L29=""),"",IF(K29>L29,"1",IF(K29<L29,"2","X"))) -> 1 | N29: =IF(M29="","",IF(M29="1",I29,IF(M29="2",J29,"Oavgjort"))) -> Tyskland | P29: =B22 -> Australien | Q29: =SUMPRODUCT(($H$5:$H$76="D")*($I$5:$I$76=P29)*($K$5:$K$76<>"")*($K$5:$K$76>$L$5:$L$76))+SUMPRODUCT(($H$5:$H$76="D")*($J$5:$J$76=P29)*($L$5:$L$76<>"")*($L$5:$L$76>$K$5:$K$76)) -> 1 | R29: =SUMPRODUCT(($H$5:$H$76="D")*(($I$5:$I$76=P29)+($J$5:$J$76=P29))*($K$5:$K$76<>"")*($K$5:$K$76=$L$5:$L$76)) -> 1 | S29: =SUMPRODUCT(($H$5:$H$76="D")*($I$5:$I$76=P29)*($K$5:$K$76<>"")*($K$5:$K$76<$L$5:$L$76))+SUMPRODUCT(($H$5:$H$76="D")*($J$5:$J$76=P29)*($L$5:$L$76<>"")*($L$5:$L$76<$K$5:$K$76)) -> 1 | T29: =SUMIFS($K$5:$K$76,$H$5:$H$76,"D",$I$5:$I$76,P29)+SUMIFS($L$5:$L$76,$H$5:$H$76,"D",$J$5:$J$76,P29) -> 2 | U29: =SUMIFS($L$5:$L$76,$H$5:$H$76,"D",$I$5:$I$76,P29)+SUMIFS($K$5:$K$76,$H$5:$H$76,"D",$J$5:$J$76,P29) -> 2 | V29: =T29-U29 -> 0 | W29: =Q29*3+R29 -> 4
A30: F1 | B30: Nederländerna | C30: 26 | D30: 46188 | E30: 0.041666667 | F30: Lincoln Financial Field (Philadelphia) | G30: Gruppspel | H30: E | I30: Elfenbenskusten | J30: Ecuador | K30: 1 | L30: 0 | M30: =IF(OR(K30="",L30=""),"",IF(K30>L30,"1",IF(K30<L30,"2","X"))) -> 1 | N30: =IF(M30="","",IF(M30="1",I30,IF(M30="2",J30,"Oavgjort"))) -> Elfenbenskusten | P30: =B23 -> Turkiet | Q30: =SUMPRODUCT(($H$5:$H$76="D")*($I$5:$I$76=P30)*($K$5:$K$76<>"")*($K$5:$K$76>$L$5:$L$76))+SUMPRODUCT(($H$5:$H$76="D")*($J$5:$J$76=P30)*($L$5:$L$76<>"")*($L$5:$L$76>$K$5:$K$76)) -> 1 | R30: =SUMPRODUCT(($H$5:$H$76="D")*(($I$5:$I$76=P30)+($J$5:$J$76=P30))*($K$5:$K$76<>"")*($K$5:$K$76=$L$5:$L$76)) -> 0 | S30: =SUMPRODUCT(($H$5:$H$76="D")*($I$5:$I$76=P30)*($K$5:$K$76<>"")*($K$5:$K$76<$L$5:$L$76))+SUMPRODUCT(($H$5:$H$76="D")*($J$5:$J$76=P30)*($L$5:$L$76<>"")*($L$5:$L$76<$K$5:$K$76)) -> 2 | T30: =SUMIFS($K$5:$K$76,$H$5:$H$76,"D",$I$5:$I$76,P30)+SUMIFS($L$5:$L$76,$H$5:$H$76,"D",$J$5:$J$76,P30) -> 3 | U30: =SUMIFS($L$5:$L$76,$H$5:$H$76,"D",$I$5:$I$76,P30)+SUMIFS($K$5:$K$76,$H$5:$H$76,"D",$J$5:$J$76,P30) -> 5 | V30: =T30-U30 -> -2 | W30: =Q30*3+R30 -> 3
A31: F2 | B31: Japan | C31: 27 | D31: 46194 | E31: 0.083333333 | F31: Arrowhead Stadium (Kansas City) | G31: Gruppspel | H31: E | I31: Ecuador | J31: Curaçao | K31: 0 | L31: 0 | M31: =IF(OR(K31="",L31=""),"",IF(K31>L31,"1",IF(K31<L31,"2","X"))) -> X | N31: =IF(M31="","",IF(M31="1",I31,IF(M31="2",J31,"Oavgjort"))) -> Oavgjort
A32: F3 | B32: Sverige | C32: 28 | D32: 46193 | E32: 0.91666667 | F32: BMO Field (Toronto) | G32: Gruppspel | H32: E | I32: Tyskland | J32: Elfenbenskusten | K32: 2 | L32: 1 | M32: =IF(OR(K32="",L32=""),"",IF(K32>L32,"1",IF(K32<L32,"2","X"))) -> 1 | N32: =IF(M32="","",IF(M32="1",I32,IF(M32="2",J32,"Oavgjort"))) -> Tyskland | P32: Grupp E
A33: F4 | B33: Tunisien | C33: 29 | D33: 46198 | E33: 0.91666667 | F33: MetLife Stadium (New York/New Jersey) | G33: Gruppspel | H33: E | I33: Ecuador | J33: Tyskland | K33: 2 | L33: 1 | M33: =IF(OR(K33="",L33=""),"",IF(K33>L33,"1",IF(K33<L33,"2","X"))) -> 1 | N33: =IF(M33="","",IF(M33="1",I33,IF(M33="2",J33,"Oavgjort"))) -> Ecuador | P33: Lag | Q33: V | R33: O | S33: F | T33: GM | U33: IM | V33: +/- | W33: P
A34: Grupp G | C34: 30 | D34: 46198 | E34: 0.91666667 | F34: Lincoln Financial Field (Philadelphia) | G34: Gruppspel | H34: E | I34: Curaçao | J34: Elfenbenskusten | K34: 0 | L34: 2 | M34: =IF(OR(K34="",L34=""),"",IF(K34>L34,"1",IF(K34<L34,"2","X"))) -> 2 | N34: =IF(M34="","",IF(M34="1",I34,IF(M34="2",J34,"Oavgjort"))) -> Elfenbenskusten | P34: =B25 -> Tyskland | Q34: =SUMPRODUCT(($H$5:$H$76="E")*($I$5:$I$76=P34)*($K$5:$K$76<>"")*($K$5:$K$76>$L$5:$L$76))+SUMPRODUCT(($H$5:$H$76="E")*($J$5:$J$76=P34)*($L$5:$L$76<>"")*($L$5:$L$76>$K$5:$K$76)) -> 2 | R34: =SUMPRODUCT(($H$5:$H$76="E")*(($I$5:$I$76=P34)+($J$5:$J$76=P34))*($K$5:$K$76<>"")*($K$5:$K$76=$L$5:$L$76)) -> 0 | S34: =SUMPRODUCT(($H$5:$H$76="E")*($I$5:$I$76=P34)*($K$5:$K$76<>"")*($K$5:$K$76<$L$5:$L$76))+SUMPRODUCT(($H$5:$H$76="E")*($J$5:$J$76=P34)*($L$5:$L$76<>"")*($L$5:$L$76<$K$5:$K$76)) -> 1 | T34: =SUMIFS($K$5:$K$76,$H$5:$H$76,"E",$I$5:$I$76,P34)+SUMIFS($L$5:$L$76,$H$5:$H$76,"E",$J$5:$J$76,P34) -> 10 | U34: =SUMIFS($L$5:$L$76,$H$5:$H$76,"E",$I$5:$I$76,P34)+SUMIFS($K$5:$K$76,$H$5:$H$76,"E",$J$5:$J$76,P34) -> 4 | V34: =T34-U34 -> 6 | W34: =Q34*3+R34 -> 6
A35: G1 | B35: Belgien | C35: 31 | D35: 46187 | E35: 0.91666667 | F35: AT&T Stadium (Dallas) | G35: Gruppspel | H35: F | I35: Nederländerna | J35: Japan | K35: 2 | L35: 2 | M35: =IF(OR(K35="",L35=""),"",IF(K35>L35,"1",IF(K35<L35,"2","X"))) -> X | N35: =IF(M35="","",IF(M35="1",I35,IF(M35="2",J35,"Oavgjort"))) -> Oavgjort | P35: =B26 -> Curaçao | Q35: =SUMPRODUCT(($H$5:$H$76="E")*($I$5:$I$76=P35)*($K$5:$K$76<>"")*($K$5:$K$76>$L$5:$L$76))+SUMPRODUCT(($H$5:$H$76="E")*($J$5:$J$76=P35)*($L$5:$L$76<>"")*($L$5:$L$76>$K$5:$K$76)) -> 0 | R35: =SUMPRODUCT(($H$5:$H$76="E")*(($I$5:$I$76=P35)+($J$5:$J$76=P35))*($K$5:$K$76<>"")*($K$5:$K$76=$L$5:$L$76)) -> 1 | S35: =SUMPRODUCT(($H$5:$H$76="E")*($I$5:$I$76=P35)*($K$5:$K$76<>"")*($K$5:$K$76<$L$5:$L$76))+SUMPRODUCT(($H$5:$H$76="E")*($J$5:$J$76=P35)*($L$5:$L$76<>"")*($L$5:$L$76<$K$5:$K$76)) -> 2 | T35: =SUMIFS($K$5:$K$76,$H$5:$H$76,"E",$I$5:$I$76,P35)+SUMIFS($L$5:$L$76,$H$5:$H$76,"E",$J$5:$J$76,P35) -> 1 | U35: =SUMIFS($L$5:$L$76,$H$5:$H$76,"E",$I$5:$I$76,P35)+SUMIFS($K$5:$K$76,$H$5:$H$76,"E",$J$5:$J$76,P35) -> 9 | V35: =T35-U35 -> -8 | W35: =Q35*3+R35 -> 1
A36: G2 | B36: Egypten | C36: 32 | D36: 46188 | E36: 0.16666667 | F36: Estadio BBVA (Monterrey) | G36: Gruppspel | H36: F | I36: Sverige | J36: Tunisien | K36: 5 | L36: 1 | M36: =IF(OR(K36="",L36=""),"",IF(K36>L36,"1",IF(K36<L36,"2","X"))) -> 1 | N36: =IF(M36="","",IF(M36="1",I36,IF(M36="2",J36,"Oavgjort"))) -> Sverige | P36: =B27 -> Elfenbenskusten | Q36: =SUMPRODUCT(($H$5:$H$76="E")*($I$5:$I$76=P36)*($K$5:$K$76<>"")*($K$5:$K$76>$L$5:$L$76))+SUMPRODUCT(($H$5:$H$76="E")*($J$5:$J$76=P36)*($L$5:$L$76<>"")*($L$5:$L$76>$K$5:$K$76)) -> 2 | R36: =SUMPRODUCT(($H$5:$H$76="E")*(($I$5:$I$76=P36)+($J$5:$J$76=P36))*($K$5:$K$76<>"")*($K$5:$K$76=$L$5:$L$76)) -> 0 | S36: =SUMPRODUCT(($H$5:$H$76="E")*($I$5:$I$76=P36)*($K$5:$K$76<>"")*($K$5:$K$76<$L$5:$L$76))+SUMPRODUCT(($H$5:$H$76="E")*($J$5:$J$76=P36)*($L$5:$L$76<>"")*($L$5:$L$76<$K$5:$K$76)) -> 1 | T36: =SUMIFS($K$5:$K$76,$H$5:$H$76,"E",$I$5:$I$76,P36)+SUMIFS($L$5:$L$76,$H$5:$H$76,"E",$J$5:$J$76,P36) -> 4 | U36: =SUMIFS($L$5:$L$76,$H$5:$H$76,"E",$I$5:$I$76,P36)+SUMIFS($K$5:$K$76,$H$5:$H$76,"E",$J$5:$J$76,P36) -> 2 | V36: =T36-U36 -> 2 | W36: =Q36*3+R36 -> 6
A37: G3 | B37: Iran | C37: 33 | D37: 46194 | E37: 0.25 | F37: Estadio BBVA (Monterrey) | G37: Gruppspel | H37: F | I37: Tunisien | J37: Japan | K37: 0 | L37: 4 | M37: =IF(OR(K37="",L37=""),"",IF(K37>L37,"1",IF(K37<L37,"2","X"))) -> 2 | N37: =IF(M37="","",IF(M37="1",I37,IF(M37="2",J37,"Oavgjort"))) -> Japan | P37: =B28 -> Ecuador | Q37: =SUMPRODUCT(($H$5:$H$76="E")*($I$5:$I$76=P37)*($K$5:$K$76<>"")*($K$5:$K$76>$L$5:$L$76))+SUMPRODUCT(($H$5:$H$76="E")*($J$5:$J$76=P37)*($L$5:$L$76<>"")*($L$5:$L$76>$K$5:$K$76)) -> 1 | R37: =SUMPRODUCT(($H$5:$H$76="E")*(($I$5:$I$76=P37)+($J$5:$J$76=P37))*($K$5:$K$76<>"")*($K$5:$K$76=$L$5:$L$76)) -> 1 | S37: =SUMPRODUCT(($H$5:$H$76="E")*($I$5:$I$76=P37)*($K$5:$K$76<>"")*($K$5:$K$76<$L$5:$L$76))+SUMPRODUCT(($H$5:$H$76="E")*($J$5:$J$76=P37)*($L$5:$L$76<>"")*($L$5:$L$76<$K$5:$K$76)) -> 1 | T37: =SUMIFS($K$5:$K$76,$H$5:$H$76,"E",$I$5:$I$76,P37)+SUMIFS($L$5:$L$76,$H$5:$H$76,"E",$J$5:$J$76,P37) -> 2 | U37: =SUMIFS($L$5:$L$76,$H$5:$H$76,"E",$I$5:$I$76,P37)+SUMIFS($K$5:$K$76,$H$5:$H$76,"E",$J$5:$J$76,P37) -> 2 | V37: =T37-U37 -> 0 | W37: =Q37*3+R37 -> 4
A38: G4 | B38: Nya Zeeland | C38: 34 | D38: 46193 | E38: 0.79166667 | F38: NRG Stadium (Houston) | G38: Gruppspel | H38: F | I38: Nederländerna | J38: Sverige | K38: 5 | L38: 1 | M38: =IF(OR(K38="",L38=""),"",IF(K38>L38,"1",IF(K38<L38,"2","X"))) -> 1 | N38: =IF(M38="","",IF(M38="1",I38,IF(M38="2",J38,"Oavgjort"))) -> Nederländerna
A39: Grupp H | C39: 35 | D39: 46199 | E39: 0.041666667 | F39: Arrowhead Stadium (Kansas City) | G39: Gruppspel | H39: F | I39: Tunisien | J39: Nederländerna | K39: 1 | L39: 3 | M39: =IF(OR(K39="",L39=""),"",IF(K39>L39,"1",IF(K39<L39,"2","X"))) -> 2 | N39: =IF(M39="","",IF(M39="1",I39,IF(M39="2",J39,"Oavgjort"))) -> Nederländerna | P39: Grupp F
A40: H1 | B40: Spanien | C40: 36 | D40: 46199 | E40: 0.041666667 | F40: AT&T Stadium (Dallas) | G40: Gruppspel | H40: F | I40: Japan | J40: Sverige | K40: 1 | L40: 1 | M40: =IF(OR(K40="",L40=""),"",IF(K40>L40,"1",IF(K40<L40,"2","X"))) -> X | N40: =IF(M40="","",IF(M40="1",I40,IF(M40="2",J40,"Oavgjort"))) -> Oavgjort | P40: Lag | Q40: V | R40: O | S40: F | T40: GM | U40: IM | V40: +/- | W40: P
A41: H2 | B41: Kap Verde | C41: 37 | D41: 46188 | E41: 0.875 | F41: Lumen Field (Seattle) | G41: Gruppspel | H41: G | I41: Belgien | J41: Egypten | K41: 1 | L41: 1 | M41: =IF(OR(K41="",L41=""),"",IF(K41>L41,"1",IF(K41<L41,"2","X"))) -> X | N41: =IF(M41="","",IF(M41="1",I41,IF(M41="2",J41,"Oavgjort"))) -> Oavgjort | P41: =B30 -> Nederländerna | Q41: =SUMPRODUCT(($H$5:$H$76="F")*($I$5:$I$76=P41)*($K$5:$K$76<>"")*($K$5:$K$76>$L$5:$L$76))+SUMPRODUCT(($H$5:$H$76="F")*($J$5:$J$76=P41)*($L$5:$L$76<>"")*($L$5:$L$76>$K$5:$K$76)) -> 2 | R41: =SUMPRODUCT(($H$5:$H$76="F")*(($I$5:$I$76=P41)+($J$5:$J$76=P41))*($K$5:$K$76<>"")*($K$5:$K$76=$L$5:$L$76)) -> 1 | S41: =SUMPRODUCT(($H$5:$H$76="F")*($I$5:$I$76=P41)*($K$5:$K$76<>"")*($K$5:$K$76<$L$5:$L$76))+SUMPRODUCT(($H$5:$H$76="F")*($J$5:$J$76=P41)*($L$5:$L$76<>"")*($L$5:$L$76<$K$5:$K$76)) -> 0 | T41: =SUMIFS($K$5:$K$76,$H$5:$H$76,"F",$I$5:$I$76,P41)+SUMIFS($L$5:$L$76,$H$5:$H$76,"F",$J$5:$J$76,P41) -> 10 | U41: =SUMIFS($L$5:$L$76,$H$5:$H$76,"F",$I$5:$I$76,P41)+SUMIFS($K$5:$K$76,$H$5:$H$76,"F",$J$5:$J$76,P41) -> 4 | V41: =T41-U41 -> 6 | W41: =Q41*3+R41 -> 7
...

Sheet Poäng & instruktioner
A1: 🏆 VM-tips 2026
A3: Poängräkning | D3: Instruktioner
A4: Rätt antal mål per lag i match | B4: 2 poäng per lag | D4: Fyll i lag i gula celler på ”Resultat & Tabell”.
A5: Rätt tecken (1/X/2) | B5: 2 poäng | D5: Fyll i faktiska resultat i gula målceller när matcherna spelas.
A6: Rätt lag till åttondelsfinal | B6: 2 poäng per lag | D6: Kopiera ”Tippare Mall” en gång per deltagare och döp fliken till deltagarens namn.
A7: Rätt lag till kvartsfinal | B7: 4 poäng per lag | D7: Deltagarna fyller i sina tips i gula celler innan turneringen startar.
A8: Rätt lag till semifinal | B8: 6 poäng per lag
A9: Rätt lag till final | B9: 8 poäng per lag | D9: VM 2026-formatet är 48 lag, 12 grupper och 104 matcher. Den här filen är nollställd med platshållare.
A10: Världsmästare | B10: 20 poäng
A11: Skyttekung | B11: 20 poäng
A14: Källa grupper: | B14: FIFA/Reuters/Fox Sports, kontrollerat 2026-05-25
A15: Obs: Det är resultat efter ordinarie tid som gäller

Sheet Favoriter & Odds
A1: Land | B1: Odds | C1: Vinstchans | P1: Spelare | Q1: Odds | R1: Vinstchans
A2: 🥇 🇪🇸 Spanien | B2: 5.5 | C2: =1/B2 -> 0.18181818 | P2: 🥇 🇫🇷 Kylian Mbappé | Q2: 7 | R2: =1/Q2 -> 0.14285714
A3: 🥈 🇫🇷 Frankrike | B3: 6.5 | C3: =1/B3 -> 0.15384615 | P3: 🥈 🏴 Harry Kane | Q3: 8 | R3: =1/Q3 -> 0.125
A4: 🥉 🏴 England | B4: 7.5 | C4: =1/B4 -> 0.13333333 | P4: 🥉 🇦🇷 Lionel Messi | Q4: 13 | R4: =1/Q4 -> 0.076923077
A5: 🇧🇷 Brasilien | B5: 9 | C5: =1/B5 -> 0.11111111 | P5: 🇳🇴 Erling Haaland | Q5: 15 | R5: =1/Q5 -> 0.066666667
A6: 🇦🇷 Argentina | B6: 9 | C6: =1/B6 -> 0.11111111 | P6: 🇪🇸 Lamine Yamal | Q6: 15 | R6: =1/Q6 -> 0.066666667
A7: 🇵🇹 Portugal | B7: 12 | C7: =1/B7 -> 0.083333333 | P7: 🇧🇷 Vinícius Júnior | Q7: 19 | R7: =1/Q7 -> 0.052631579
A8: 🇩🇪 Tyskland | B8: 16 | C8: =1/B8 -> 0.0625 | P8: 🇦🇷 Lautaro Martínez | Q8: 21 | R8: =1/Q8 -> 0.047619048
A9: 🇳🇱 Nederländerna | B9: 25 | C9: =1/B9 -> 0.04 | P9: 🇫🇷 Ousmane Dembélé | Q9: 21 | R9: =1/Q9 -> 0.047619048
A10: 🇧🇪 Belgien | B10: 26 | C10: =1/B10 -> 0.038461538 | P10: 🇧🇪 Romelu Lukaku | Q10: 21 | R10: =1/Q10 -> 0.047619048
A11: 🇳🇴 Norge | B11: 29 | C11: =1/B11 -> 0.034482759 | P11: 🏴 Bukayo Saka | Q11: 34 | R11: =1/Q11 -> 0.029411765
A12: 🇭🇷 Kroatien | B12: 41 | C12: =1/B12 -> 0.024390244 | P12: 🇦🇷 Julián Álvarez | Q12: 41 | R12: =1/Q12 -> 0.024390244
A13: 🇲🇦 Marocko | B13: 51 | C13: =1/B13 -> 0.019607843 | P13: 🇫🇷 Michael Olise | Q13: 41 | R13: =1/Q13 -> 0.024390244
... A16: 🇲🇽 Mexiko | B16: 81 | C16: =1/B16 -> 0.012345679 | P16: 🇧🇷 João Pedro | Q16: 67 | R16: =1/Q16 -> 0.014925373
A17: 🇯🇵 Japan | B17: 81 | C17: =1/B17 -> 0.012345679
A18: 🇨🇴 Colombia | B18: 81 | C18: =1/B18 -> 0.012345679
A19: 🇩🇰 Danmark | B19: 101 | C19: =1/B19 -> 0.0099009901
A20: 🇸🇳 Senegal | B20: 101 | C20: =1/B20 -> 0.0099009901
A21: 🇸🇪 Sverige | B21: 151 | C21: =1/B21 -> 0.0066225166

Sheet tippare mall
A1: 🎯 Tippare Mall – kopiera fliken och döp om till deltagarens namn
W2: Slutspel-hjälp
A3: Matchnr | B3: Fas | C3: Grupp | D3: Hemmalag | E3: Bortalag | F3: Tips H | G3: Tips B | H3: Tecken | I3: Poäng mål | J3: Poäng tecken | K3: Poäng totalt | L3: Tippad grupptabell | N3: 2 | O3: 3 | P3: 4 | Q3: 5 | R3: 6 | S3: 7 | T3: 8 | W3: Grupp | X3: 1:a | Y3: 2:a | Z3: 3:a | AA3: 3:a rankvärde | AB3: 3:a rank | AC3: Kommentar
A4: 1 | B4: Gruppspel | C4: A | D4: Mexico | E4: South Africa | H4: =IF(OR(F4="",G4=""),"",IF(F4>G4,"1",IF(F4<G4,"2","X"))) | I4: =IF(OR(F4="",G4="",'📊 Resultat & Tabell'!K5="",'📊 Resultat & Tabell'!L5=""),"",IF(F4='📊 Resultat & Tabell'!K5,2,0)+IF(G4='📊 Resultat & Tabell'!L5,2,0)) | J4: =IF(OR(H4="",'📊 Resultat & Tabell'!M5=""),"",IF(H4='📊 Resultat & Tabell'!M5,2,0)) | K4: =IF(AND(I4="",J4=""),"",N(I4)+N(J4)) | L4: Grupp A | W4: A | X4: {=IF(COUNTIFS($C$4:$C$75,"A",$F$4:$F$75,"<>",$G$4:$G$75,"<>")=0,"",IFERROR(INDEX($L$6:$L$9,MATCH(LARGE($T$6:$T$9+ROW($T$6:$T$9)/100000,1),$T$6:$T$9+ROW($T$6:$T$9)/100000,0)),""))} | Y4: {=IF(COUNTIFS($C$4:$C$75,"A",$F$4:$F$75,"<>",$G$4:$G$75,"<>")=0,"",IFERROR(INDEX($L$6:$L$9,MATCH(LARGE($T$6:$T$9+ROW($T$6:$T$9)/100000,2),$T$6:$T$9+ROW($T$6:$T$9)/100000,0)),""))} | Z4: {=IF(COUNTIFS($C$4:$C$75,"A",$F$4:$F$75,"<>",$G$4:$G$75,"<>")=0,"",IFERROR(INDEX($L$6:$L$9,MATCH(LARGE($T$6:$T$9+ROW($T$6:$T$9)/100000,3),$T$6:$T$9+ROW($T$6:$T$9)/100000,0)),""))} | AA4: =IF(COUNTIFS($C$4:$C$75,"A",$F$4:$F$75,"<>",$G$4:$G$75,"<>")=0,"",IFERROR(LARGE($T$6:$T$9,3),"")) | AB4: =IF(AA4="","",_xlfn.RANK.EQ(AA4,$AA$4:$AA$15,0))
A5: 2 | B5: Gruppspel | C5: A | D5: Sydkorea | E5: Tjeckien | H5: =IF(OR(F5="",G5=""),"",IF(F5>G5,"1",IF(F5<G5,"2","X"))) | I5: =IF(OR(F5="",G5="",'📊 Resultat & Tabell'!K6="",'📊 Resultat & Tabell'!L6=""),"",IF(F5='📊 Resultat & Tabell'!K6,2,0)+IF(G5='📊 Resultat & Tabell'!L6,2,0)) | J5: =IF(OR(H5="",'📊 Resultat & Tabell'!M6=""),"",IF(H5='📊 Resultat & Tabell'!M6,2,0)) | K5: =IF(AND(I5="",J5=""),"",N(I5)+N(J5)) | L5: Lag | M5: V | N5: O | O5: F | P5: GM | Q5: IM | R5: +/- | S5: P | T5: Rankvärde | W5: B | X5: {=IF(COUNTIFS($C$4:$C$75,"B",$F$4:$F$75,"<>",$G$4:$G$75,"<>")=0,"",IFERROR(INDEX($L$13:$L$16,MATCH(LARGE($T$13:$T$16+ROW($T$13:$T$16)/100000,1),$T$13:$T$16+ROW($T$13:$T$16)/100000,0)),""))} | Y5: {=IF(COUNTIFS($C$4:$C$75,"B",$F$4:$F$75,"<>",$G$4:$G$75,"<>")=0,"",IFERROR(INDEX($L$13:$L$16,MATCH(LARGE($T$13:$T$16+ROW($T$13:$T$16)/100000,2),$T$13:$T$16+ROW($T$13:$T$16)/100000,0)),""))} | Z5: {=IF(COUNTIFS($C$4:$C$75,"B",$F$4:$F$75,"<>",$G$4:$G$75,"<>")=0,"",IFERROR(INDEX($L$13:$L$16,MATCH(LARGE($T$13:$T$16+ROW($T$13:$T$16)/100000,3),$T$13:$T$16+ROW($T$13:$T$16)/100000,0)),""))} | AA5: {=IF(COUNTIFS($C$4:$C$75,"B",$F$4:$F$75,"<>",$G$4:$G$75,"<>")=0,"",LARGE($T$13:$T$16+ROW($T$13:$T$16)/100000,3))} | AB5: =IF(AA5="","",_xlfn.RANK.EQ(AA5,$AA$4:$AA$15,0))
A6: 3 | B6: Gruppspel | C6: A | D6: Tjeckien | E6: South Africa | H6: =IF(OR(F6="",G6=""),"",IF(F6>G6,"1",IF(F6<G6,"2","X"))) | I6: =IF(OR(F6="",G6="",'📊 Resultat & Tabell'!K7="",'📊 Resultat & Tabell'!L7=""),"",IF(F6='📊 Resultat & Tabell'!K7,2,0)+IF(G6='📊 Resultat & Tabell'!L7,2,0)) | J6: =IF(OR(H6="",'📊 Resultat & Tabell'!M7=""),"",IF(H6='📊 Resultat & Tabell'!M7,2,0)) | K6: =IF(AND(I6="",J6=""),"",N(I6)+N(J6)) | L6: Mexico | M6: {=SUMPRODUCT(--($C$4:$C$75="A"),--($D$4:$D$75=L6),--($F$4:$F$75>$G$4:$G$75),--($F$4:$F$75<>""),--($G$4:$G$75<>""))+SUMPRODUCT(--($C$4:$C$75="A"),--($E$4:$E$75=L6),--($G$4:$G$75>$F$4:$F$75),--($F$4:$F$75<>""),--($G$4:$G$75<>""))} -> 0 | N6: {=SUMPRODUCT(--($C$4:$C$75="A"),--(($D$4:$D$75=L6)+($E$4:$E$75=L6)>0),--($F$4:$F$75=$G$4:$G$75),--($F$4:$F$75<>""),--($G$4:$G$75<>""))} -> 0 | O6: {=SUMPRODUCT(--($C$4:$C$75="A"),--($D$4:$D$75=L6),--($F$4:$F$75<$G$4:$G$75),--($F$4:$F$75<>""),--($G$4:$G$75<>""))+SUMPRODUCT(--($C$4:$C$75="A"),--($E$4:$E$75=L6),--($G$4:$G$75<$F$4:$F$75),--($F$4:$F$75<>""),--($G$4:$G$75<>""))} -> 0 | P6: {=SUMPRODUCT(--($C$4:$C$75="A"),--($D$4:$D$75=L6),$F$4:$F$75,--($F$4:$F$75<>""),--($G$4:$G$75<>""))+SUMPRODUCT(--($C$4:$C$75="A"),--($E$4:$E$75=L6),$G$4:$G$75,--($F$4:$F$75<>""),--($G$4:$G$75<>""))} -> 0 | Q6: {=SUMPRODUCT(--($C$4:$C$75="A"),--($D$4:$D$75=L6),$G$4:$G$75,--($F$4:$F$75<>""),--($G$4:$G$75<>""))+SUMPRODUCT(--($C$4:$C$75="A"),--($E$4:$E$75=L6),$F$4:$F$75,--($F$4:$F$75<>""),--($G$4:$G$75<>""))} -> 0 | R6: =P6-Q6 -> 0 | S6: =M6*3+N6 -> 0 | T6: =S6*100000+R6*1000+P6 -> 0 | W6: C | X6: {=IF(COUNTIFS($C$4:$C$75,"C",$F$4:$F$75,"<>",$G$4:$G$75,"<>")=0,"",IFERROR(INDEX($L$20:$L$23,MATCH(LARGE($T$20:$T$23+ROW($T$20:$T$23)/100000,1),$T$20:$T$23+ROW($T$20:$T$23)/100000,0)),""))} | Y6: {=IF(COUNTIFS($C$4:$C$75,"C",$F$4:$F$75,"<>",$G$4:$G$75,"<>")=0,"",IFERROR(INDEX($L$20:$L$23,MATCH(LARGE($T$20:$T$23+ROW($T$20:$T$23)/100000,2),$T$20:$T$23+ROW($T$20:$T$23)/100000,0)),""))} | Z6: {=IF(COUNTIFS($C$4:$C$75,"C",$F$4:$F$75,"<>",$G$4:$G$75,"<>")=0,"",IFERROR(INDEX($L$20:$L$23,MATCH(LARGE($T$20:$T$23+ROW($T$20:$T$23)/100000,3),$T$20:$T$23+ROW($T$20:$T$23)/100000,0)),""))} | AA6: {=IF(COUNTIFS($C$4:$C$75,"C",$F$4:$F$75,"<>",$G$4:$G$75,"<>")=0,"",LARGE($T$20:$T$23+ROW($T$20:$T$23)/100000,3))} | AB6: =IF(AA6="","",_xlfn.RANK.EQ(AA6,$AA$4:$AA$15,0))
A7: 4 | B7: Gruppspel | C7: A | D7: Mexico | E7: Sydkorea | H7: =IF(OR(F7="",G7=""),"",IF(F7>G7,"1",IF(F7<G7,"2","X"))) | I7: =IF(OR(F7="",G7="",'📊 Resultat & Tabell'!K8="",'📊 Resultat & Tabell'!L8=""),"",IF(F7='📊 Resultat & Tabell'!K8,2,0)+IF(G7='📊 Resultat & Tabell'!L8,2,0)) | J7: =IF(OR(H7="",'📊 Resultat & Tabell'!M8=""),"",IF(H7='📊 Resultat & Tabell'!M8,2,0)) | K7: =IF(AND(I7="",J7=""),"",N(I7)+N(J7)) | L7: South Africa | M7: {=SUMPRODUCT(--($C$4:$C$75="A"),--($D$4:$D$75=L7),--($F$4:$F$75>$G$4:$G$75),--($F$4:$F$75<>""),--($G$4:$G$75<>""))+SUMPRODUCT(--($C$4:$C$75="A"),--($E$4:$E$75=L7),--($G$4:$G$75>$F$4:$F$75),--($F$4:$F$75<>""),--($G$4:$G$75<>""))} -> 0 | N7: {=SUMPRODUCT(--($C$4:$C$75="A"),--(($D$4:$D$75=L7)+($E$4:$E$75=L7)>0),--($F$4:$F$75=$G$4:$G$75),--($F$4:$F$75<>""),--($G$4:$G$75<>""))} -> 0 | O7: {=SUMPRODUCT(--($C$4:$C$75="A"),--($D$4:$D$75=L7),--($F$4:$F$75<$G$4:$G$75),--($F$4:$F$75<>""),--($G$4:$G$75<>""))+SUMPRODUCT(--($C$4:$C$75="A"),--($E$4:$E$75=L7),--($G$4:$G$75<$F$4:$F$75),--($F$4:$F$75<>""),--($G$4:$G$75<>""))} -> 0 | P7: {=SUMPRODUCT(--($C$4:$C$75="A"),--($D$4:$D$75=L7),$F$4:$F$75,--($F$4:$F$75<>""),--($G$4:$G$75<>""))+SUMPRODUCT(--($C$4:$C$75="A"),--($E$4:$E$75=L7),$G$4:$G$75,--($F$4:$F$75<>""),--($G$4:$G$75<>""))} -> 0 | Q7: {=SUMPRODUCT(--($C$4:$C$75="A"),--($D$4:$D$75=L7),$G$4:$G$75,--($F$4:$F$75<>""),--($G$4:$G$75<>""))+SUMPRODUCT(--($C$4:$C$75="A"),--($E$4:$E$75=L7),$F$4:$F$75,--($F$4:$F$75<>""),--($G$4:$G$75<>""))} -> 0 | R7: =P7-Q7 -> 0 | S7: =M7*3+N7 -> 0 | T7: =S7*100000+R7*1000+P7 -> 0 | W7: D | X7: {=IF(COUNTIFS($C$4:$C$75,"D",$F$4:$F$75,"<>",$G$4:$G$75,"<>")=0,"",IFERROR(INDEX($L$27:$L$30,MATCH(LARGE($T$27:$T$30+ROW($T$27:$T$30)/100000,1),$T$27:$T$30+ROW($T$27:$T$30)/100000,0)),""))} | Y7: {=IF(COUNTIFS($C$4:$C$75,"D",$F$4:$F$75,"<>",$G$4:$G$75,"<>")=0,"",IFERROR(INDEX($L$27:$L$30,MATCH(LARGE($T$27:$T$30+ROW($T$27:$T$30)/100000,2),$T$27:$T$30+ROW($T$27:$T$30)/100000,0)),""))} | Z7: {=IF(COUNTIFS($C$4:$C$75,"D",$F$4:$F$75,"<>",$G$4:$G$75,"<>")=0,"",IFERROR(INDEX($L$27:$L$30,MATCH(LARGE($T$27:$T$30+ROW($T$27:$T$30)/100000,3),$T$27:$T$30+ROW($T$27:$T$30)/100000,0)),""))} | AA7: {=IF(COUNTIFS($C$4:$C$75,"D",$F$4:$F$75,"<>",$G$4:$G$75,"<>")=0,"",LARGE($T$27:$T$30+ROW($T$27:$T$30)/100000,3))} | AB7: =IF(AA7="","",_xlfn.RANK.EQ(AA7,$AA$4:$AA$15,0))
A8: 5 | B8: Gruppspel | C8: A | D8: Tjeckien | E8: Mexico | H8: =IF(OR(F8="",G8=""),"",IF(F8>G8,"1",IF(F8<G8,"2","X"))) | I8: =IF(OR(F8="",G8="",'📊 Resultat & Tabell'!K9="",'📊 Resultat & Tabell'!L9=""),"",IF(F8='📊 Resultat & Tabell'!K9,2,0)+IF(G8='📊 Resultat & Tabell'!L9,2,0)) | J8: =IF(OR(H8="",'📊 Resultat & Tabell'!M9=""),"",IF(H8='📊 Resultat & Tabell'!M9,2,0)) | K8: =IF(AND(I8="",J8=""),"",N(I8)+N(J8)) | L8: Sydkorea | M8: {=SUMPRODUCT(--($C$4:$C$75="A"),--($D$4:$D$75=L8),--($F$4:$F$75>$G$4:$G$75),--($F$4:$F$75<>""),--($G$4:$G$75<>""))+SUMPRODUCT(--($C$4:$C$75="A"),--($E$4:$E$75=L8),--($G$4:$G$75>$F$4:$F$75),--($F$4:$F$75<>""),--($G$4:$G$75<>""))} -> 0 | N8: {=SUMPRODUCT(--($C$4:$C$75="A"),--(($D$4:$D$75=L8)+($E$4:$E$75=L8)>0),--($F$4:$F$75=$G$4:$G$75),--($F$4:$F$75<>""),--($G$4:$G$75<>""))} -> 0 | O8: {=SUMPRODUCT(--($C$4:$C$75="A"),--($D$4:$D$75=L8),--($F$4:$F$75<$G$4:$G$75),--($F$4:$F$75<>""),--($G$4:$G$75<>""))+SUMPRODUCT(--($C$4:$C$75="A"),--($E$4:$E$75=L8),--($G$4:$G$75<$F$4:$F$75),--($F$4:$F$75<>""),--($G$4:$G$75<>""))} -> 0 | P8: {=SUMPRODUCT(--($C$4:$C$75="A"),--($D$4:$D$75=L8),$F$4:$F$75,--($F$4:$F$75<>""),--($G$4:$G$75<>""))+SUMPRODUCT(--($C$4:$C$75="A"),--($E$4:$E$75=L8),$G$4:$G$75,--($F$4:$F$75<>""),--($G$4:$G$75<>""))} -> 0 | Q8: {=SUMPRODUCT(--($C$4:$C$75="A"),--($D$4:$D$75=L8),$G$4:$G$75,--($F$4:$F$75<>""),--($G$4:$G$75<>""))+SUMPRODUCT(--($C$4:$C$75="A"),--($E$4:$E$75=L8),$F$4:$F$75,--($F$4:$F$75<>""),--($G$4:$G$75<>""))} -> 0 | R8: =P8-Q8 -> 0 | S8: =M8*3+N8 -> 0 | T8: =S8*100000+R8*1000+P8 -> 0 | W8: E | X8: {=IF(COUNTIFS($C$4:$C$75,"E",$F$4:$F$75,"<>",$G$4:$G$75,"<>")=0,"",IFERROR(INDEX($L$34:$L$37,MATCH(LARGE($T$34:$T$37+ROW($T$34:$T$37)/100000,1),$T$34:$T$37+ROW($T$34:$T$37)/100000,0)),""))} | Y8: {=IF(COUNTIFS($C$4:$C$75,"E",$F$4:$F$75,"<>",$G$4:$G$75,"<>")=0,"",IFERROR(INDEX($L$34:$L$37,MATCH(LARGE($T$34:$T$37+ROW($T$34:$T$37)/100000,2),$T$34:$T$37+ROW($T$34:$T$37)/100000,0)),""))} | Z8: {=IF(COUNTIFS($C$4:$C$75,"E",$F$4:$F$75,"<>",$G$4:$G$75,"<>")=0,"",IFERROR(INDEX($L$34:$L$37,MATCH(LARGE($T$34:$T$37+ROW($T$34:$T$37)/100000,3),$T$34:$T$37+ROW($T$34:$T$37)/100000,0)),""))} | AA8: {=IF(COUNTIFS($C$4:$C$75,"E",$F$4:$F$75,"<>",$G$4:$G$75,"<>")=0,"",LARGE($T$34:$T$37+ROW($T$34:$T$37)/100000,3))} | AB8: =IF(AA8="","",_xlfn.RANK.EQ(AA8,$AA$4:$AA$15,0))
A9: 6 | B9: Gruppspel | C9: A | D9: South Africa | E9: Sydkorea | H9: =IF(OR(F9="",G9=""),"",IF(F9>G9,"1",IF(F9<G9,"2","X"))) | I9: =IF(OR(F9="",G9="",'📊 Resultat & Tabell'!K10="",'📊 Resultat & Tabell'!L10=""),"",IF(F9='📊 Resultat & Tabell'!K10,2,0)+IF(G9='📊 Resultat & Tabell'!L10,2,0)) | J9: =IF(OR(H9="",'📊 Resultat & Tabell'!M10=""),"",IF(H9='📊 Resultat & Tabell'!M10,2,0)) | K9: =IF(AND(I9="",J9=""),"",N(I9)+N(J9)) | L9: Tjeckien | M9: {=SUMPRODUCT(--($C$4:$C$75="A"),--($D$4:$D$75=L9),--($F$4:$F$75>$G$4:$G$75),--($F$4:$F$75<>""),--($G$4:$G$75<>""))+SUMPRODUCT(--($C$4:$C$75="A"),--($E$4:$E$75=L9),--($G$4:$G$75>$F$4:$F$75),--($F$4:$F$75<>""),--($G$4:$G$75<>""))} -> 0 | N9: {=SUMPRODUCT(--($C$4:$C$75="A"),--(($D$4:$D$75=L9)+($E$4:$E$75=L9)>0),--($F$4:$F$75=$G$4:$G$75),--($F$4:$F$75<>""),--($G$4:$G$75<>""))} -> 0 | O9: {=SUMPRODUCT(--($C$4:$C$75="A"),--($D$4:$D$75=L9),--($F$4:$F$75<$G$4:$G$75),--($F$4:$F$75<>""),--($G$4:$G$75<>""))+SUMPRODUCT(--($C$4:$C$75="A"),--($E$4:$E$75=L9),--($G$4:$G$75<$F$4:$F$75),--($F$4:$F$75<>""),--($G$4:$G$75<>""))} -> 0 | P9: {=SUMPRODUCT(--($C$4:$C$75="A"),--($D$4:$D$75=L9),$F$4:$F$75,--($F$4:$F$75<>""),--($G$4:$G$75<>""))+SUMPRODUCT(--($C$4:$C$75="A"),--($E$4:$E$75=L9),$G$4:$G$75,--($F$4:$F$75<>""),--($G$4:$G$75<>""))} -> 0 | Q9: {=SUMPRODUCT(--($C$4:$C$75="A"),--($D$4:$D$75=L9),$G$4:$G$75,--($F$4:$F$75<>""),--($G$4:$G$75<>""))+SUMPRODUCT(--($C$4:$C$75="A"),--($E$4:$E$75=L9),$F$4:$F$75,--($F$4:$F$75<>""),--($G$4:$G$75<>""))} -> 0 | R9: =P9-Q9 -> 0 | S9: =M9*3+N9 -> 0 | T9: =S9*100000+R9*1000+P9 -> 0 | W9: F | X9: {=IF(COUNTIFS($C$4:$C$75,"F",$F$4:$F$75,"<>",$G$4:$G$75,"<>")=0,"",IFERROR(INDEX($L$41:$L$44,MATCH(LARGE($T$41:$T$44+ROW($T$41:$T$44)/100000,1),$T$41:$T$44+ROW($T$41:$T$44)/100000,0)),""))} | Y9: {=IF(COUNTIFS($C$4:$C$75,"F",$F$4:$F$75,"<>",$G$4:$G$75,"<>")=0,"",IFERROR(INDEX($L$41:$L$44,MATCH(LARGE($T$41:$T$44+ROW($T$41:$T$44)/100000,2),$T$41:$T$44+ROW($T$41:$T$44)/100000,0)),""))} | Z9: {=IF(COUNTIFS($C$4:$C$75,"F",$F$4:$F$75,"<>",$G$4:$G$75,"<>")=0,"",IFERROR(INDEX($L$41:$L$44,MATCH(LARGE($T$41:$T$44+ROW($T$41:$T$44)/100000,3),$T$41:$T$44+ROW($T$41:$T$44)/100000,0)),""))} | AA9: {=IF(COUNTIFS($C$4:$C$75,"F",$F$4:$F$75,"<>",$G$4:$G$75,"<>")=0,"",LARGE($T$41:$T$44+ROW($T$41:$T$44)/100000,3))} | AB9: =IF(AA9="","",_xlfn.RANK.EQ(AA9,$AA$4:$AA$15,0))
